Workbook

Sheet Patrimoine
B2: =Contrôles!K$52 -> ✓ | C2: Patrimoine et répartition
B3: =année_courante -> 2026 | C3: Avoirs | D3: Valeur | F3: ="dont Plus value latente depuis " & YEAR(Plus_value!G3) -> dont Plus value latente depuis 2023
B4: TOTAL | C4: =COUNTA(AVRintitulé)-2 -> 26 | D4: =Avoirs!L2 -> 142580.98 | G4: =Plus_value!E3 -> 1455.0078 | H4: =Plus_value!F53 -> 0.34543877
B5: ⚓
B6: par type / compte
B7: Biens matériels | C7: =COUNTIF(AVRtype,$B7) -> 4 | D7: =SUMIF(AVRtype,$B7,AVRmontant_solde_euro) -> 126118.49 | E7: =D7/D$14 -> 0.88453934
B8: Portefeuilles | C8: =COUNTIF(AVRtype,$B8) -> 5 | D8: =SUMIF(AVRtype,$B8,AVRmontant_solde_euro) -> 2926.1684 | E8: =D8/D$14 -> 0.020522852
B9: Créances | C9: =COUNTIF(AVRtype,$B9) -> 1 | D9: =SUMIF(AVRtype,$B9,AVRmontant_solde_euro) -> 9965 | E9: =D9/D$14 -> 0.069890107
B10: Devises étrangères | C10: =COUNTIF(AVRtype,$B10) -> 3 | D10: =SUMIF(AVRtype,$B10,AVRmontant_solde_euro) -> 421.03397 | E10: =D10/D$14 -> 0.0029529462
B11: Crypto monnaies | C11: =COUNTIF(AVRtype,$B11) -> 4 | D11: =SUMIF(AVRtype,$B11,AVRmontant_solde_euro) -> 201.37668 | E11: =D11/D$14 -> 0.001412367
B12: Euros | C12: =COUNTIF(AVRtype,$B12) -> 9 | D12: =SUMIF(AVRtype,$B12,AVRmontant_solde_euro) -> 2948.92 | E12: =D12/D$14 -> 0.020682422
B13: - | C13: =COUNTIF(AVRtype,$B13) -> 0 | D13: =SUMIF(AVRtype,$B13,AVRmontant_solde_euro) -> 0 | E13: =D13/D$14 -> 0
B14: TOTAL | C14: =SUM(C7:C13) -> 26 | D14: =ROUND(SUM(D7:D13),2) -> 142580.98
B15: par sous-type
B16: Foncier | C16: =COUNTIF(AVRsous_type,$B16) -> 1 | D16: =SUMIF(AVRsous_type,B16,AVRmontant_solde_euro) -> 100000 | E16: =D16/D$25 -> 0.70135582
B17: Titres | C17: =COUNTIF(AVRsous_type,$B17) -> 5 | D17: =SUMIF(AVRsous_type,B17,AVRmontant_solde_euro) -> 2926.1684 | E17: =D17/D$25 -> 0.020522852
B18: Mobilier | C18: =COUNTIF(AVRsous_type,$B18) -> 3 | D18: =SUMIF(AVRsous_type,B18,AVRmontant_solde_euro) -> 26118.486 | E18: =D18/D$25 -> 0.18318352
B19: Euro | C19: =COUNTIF(AVRsous_type,$B19) -> 10 | D19: =SUMIF(AVRsous_type,B19,AVRmontant_solde_euro) -> 12913.92 | E19: =D19/D$25 -> 0.090572529
B20: - | C20: =COUNTIF(AVRsous_type,$B20) -> 0 | D20: =SUMIF(AVRsous_type,B20,AVRmontant_solde_euro) -> 0 | E20: =D20/D$25 -> 0
B21: Bitcoin | C21: =COUNTIF(AVRsous_type,$B21) -> 3 | D21: =SUMIF(AVRsous_type,$B21,AVRmontant_solde_euro) -> 201.37668 | E21: =D21/D$25 -> 0.001412367
B22: Dollar Singapour | C22: =COUNTIF(AVRsous_type,$B22) -> 1 | D22: =SUMIF(AVRsous_type,$B22,AVRmontant_solde_euro) -> 0 | E22: =D22/D$25 -> 0
B23: Dollar US | C23: =COUNTIF(AVRsous_type,$B23) -> 2 | D23: =SUMIF(AVRsous_type,$B23,AVRmontant_solde_euro) -> 421.03397 | E23: =D23/D$25 -> 0.0029529462
B24: Monero | C24: =COUNTIF(AVRsous_type,$B24) -> 1 | D24: =SUMIF(AVRsous_type,$B24,AVRmontant_solde_euro) -> 0 | E24: =D24/D$25 -> 0
B25: TOTAL | C25: =SUM(C16:C24) -> 26 | D25: =ROUND(SUM(D16:D24),2) -> 142580.98
B26: par domiciliation
B27: - | C27: =COUNTIF(AVRdomiciliation,$B27) -> 0 | D27: =SUMIF(AVRdomiciliation,$B27,AVRmontant_solde_euro) -> 0 | E27: =D27/D$42 -> 0
B28: Amazon | C28: =COUNTIF(AVRdomiciliation,$B28) -> 1 | D28: =SUMIF(AVRdomiciliation,$B28,AVRmontant_solde_euro) -> 50 | E28: =D28/D$42 -> 0.00035067791
B29: Auto | C29: =COUNTIF(AVRdomiciliation,$B29) -> 1 | D29: =SUMIF(AVRdomiciliation,$B29,AVRmontant_solde_euro) -> 9000 | E29: =D29/D$42 -> 0.063122024
B30: Blockchain | C30: =COUNTIF(AVRdomiciliation,$B30) -> 3 | D30: =SUMIF(AVRdomiciliation,$B30,AVRmontant_solde_euro) -> 170.09309 | E30: =D30/D$42 -> 0.0011929578
B31: BoursoBank | C31: =COUNTIF(AVRdomiciliation,$B31) -> 3 | D31: =SUMIF(AVRdomiciliation,$B31,AVRmontant_solde_euro) -> 0 | E31: =D31/D$42 -> 0
B32: Coffre | C32: =COUNTIF(AVRdomiciliation,$B32) -> 1 | D32: =SUMIF(AVRdomiciliation,$B32,AVRmontant_solde_euro) -> 2118.4859 | E32: =D32/D$42 -> 0.014858124
B33: DEGIRO | C33: =COUNTIF(AVRdomiciliation,$B33) -> 2 | D33: =SUMIF(AVRdomiciliation,$B33,AVRmontant_solde_euro) -> 0 | E33: =D33/D$42 -> 0
B34: Francine | C34: =COUNTIF(AVRdomiciliation,$B34) -> 1 | D34: =SUMIF(AVRdomiciliation,$B34,AVRmontant_solde_euro) -> 9965 | E34: =D34/D$42 -> 0.069890107
B35: Kraken | C35: =COUNTIF(AVRdomiciliation,$B35) -> 1 | D35: =SUMIF(AVRdomiciliation,$B35,AVRmontant_solde_euro) -> 31.283585 | E35: =D35/D$42 -> 0.00021940924
B36: Maison | C36: =COUNTIF(AVRdomiciliation,$B36) -> 3 | D36: =SUMIF(AVRdomiciliation,$B36,AVRmontant_solde_euro) -> 115007 | E36: =D36/D$42 -> 0.80660829
B37: Natixis | C37: =COUNTIF(AVRdomiciliation,$B37) -> 1 | D37: =SUMIF(AVRdomiciliation,$B37,AVRmontant_solde_euro) -> 0 | E37: =D37/D$42 -> 0
B38: Paypal | C38: =COUNTIF(AVRdomiciliation,$B38) -> 1 | D38: =SUMIF(AVRdomiciliation,$B38,AVRmontant_solde_euro) -> 10 | E38: =D38/D$42 -> 7.0135582e-05
... B41: eToro | C41: =COUNTIF(AVRdomiciliation,$B41) -> 2 | D41: =SUMIF(AVRdomiciliation,$B41,AVRmontant_solde_euro) -> 3347.2023 | E41: =D41/D$42 -> 0.023475798
B42: TOTAL | C42: =SUM(C27:C41) -> 26 | D42: =ROUND(SUM(D27:D41),2) -> 142580.98
B43: par titulaire
...

Sheet Avoirs
A1: 2026 | B1: Inventaire des avoirs bancaires, créances, espèces, valeurs précieuses, mobiliers, fonciers. | L1: =IF(ISERROR(L32),"✗","✓") -> ✓
A2: =Contrôles!K$52 -> ✓ | H2: Antériorité | J2: Date et solde courant | L2: =L32 -> 142580.98
A3: Intitulé | B3: Type | C3: Domiciliation | D3: Sous-type | E3: Devise | F3: Titulaire | G3: Propriété | H3: Date | I3: Montant | J3: Date | K3: Montant | L3: Montant €
A4: ⚓
A5: Assurance vie Alice | B5: Portefeuilles | C5: Société Générale | D5: Titres | E5: EUR | F5: Alice | G5: non | H5: 40664 | I5: 210000 | J5: =SUMIFS(PVLdate,PVLcompte,$A5,PVLtitre,Retenu) -> 0 | K5: =SUMIFS(PVLmontant,PVLcompte,$A5,PVLtitre,Retenu) -> 0 | L5: =K5 -> 0
A6: PEE Alice | B6: Portefeuilles | C6: Natixis | D6: Titres | E6: EUR | F6: Alice | G6: non | H6: =_xlfn.MINIFS(OPdate,OPcompte,$A6,OPdevise,$E6,OPcatégorie,Solde) -> 0 | I6: =SUMIFS(OPmontant,OPcompte,$A6,OPdevise,$E6,OPcatégorie,Solde,OPdate,$H6) -> 0 | J6: =SUMIFS(PVLdate,PVLcompte,$A6,PVLtitre,Retenu) -> 0 | K6: =SUMIFS(PVLmontant,PVLcompte,$A6,PVLtitre,Retenu) -> 0 | L6: =K6 -> 0
A7: Portefeuille BB Titres | B7: Portefeuilles | C7: BoursoBank | D7: Titres | E7: EUR | F7: Barnabé | G7: non | H7: 45485 | I7: =SUMIFS(OPmontant,OPcompte,$A7,OPdevise,$E7,OPcatégorie,Solde,OPdate,$H7) -> 0 | J7: =SUMIFS(PVLdate,PVLcompte,$A7,PVLtitre,Retenu) -> 0 | K7: =SUMIFS(PVLmontant,PVLcompte,$A7,PVLtitre,Retenu) -> 0 | L7: =K7 -> 0
A8: Portefeuille DEGIRO Titres | B8: Portefeuilles | C8: DEGIRO | D8: Titres | E8: EUR | F8: Barnabé | G8: non | H8: 45617 | I8: =SUMIFS(OPmontant,OPcompte,$A8,OPdevise,$E8,OPcatégorie,Solde,OPdate,$H8) -> 0 | J8: =SUMIFS(PVLdate,PVLcompte,$A8,PVLtitre,Retenu) -> 0 | K8: =SUMIFS(PVLmontant,PVLcompte,$A8,PVLtitre,Retenu) -> 0 | L8: =K8 -> 0
A9: Portefeuille eToro USD Titres | B9: Portefeuilles | C9: eToro | D9: Titres | E9: USD | F9: Barnabé | G9: non | H9: 45622 | I9: =SUMIFS(OPmontant,OPcompte,$A9,OPdevise,$E9,OPcatégorie,Solde,OPdate,$H9) -> 0 | J9: =SUMIFS(PVLdate,PVLcompte,$A9,PVLtitre,Retenu) -> 46083 | K9: =SUMIFS(PVLmontant,PVLcompte,$A9,PVLtitre,Retenu) -> 3388.73 | L9: =K9*cours_USD -> 2926.1684
A10: Compte Amazon | B10: Euros | C10: Amazon | D10: Euro | E10: EUR | F10: Barnabé | G10: non | H10: =_xlfn.MINIFS(OPdate,OPcompte,$A10,OPdevise,$E10,OPcatégorie,Solde) -> 45657 | I10: =SUMIFS(OPmontant,OPcompte,$A10,OPdevise,$E10,OPcatégorie,Solde,OPdate,$H10) -> 50 | J10: =_xlfn.MAXIFS(OPdate,OPcompte,$A10,OPdevise,$E10,OPcatégorie,Solde) -> 45657 | K10: =SUMIFS(OPmontant,OPcompte,$A10,OPdevise,$E10,OPcatégorie,Solde,OPdate,$J10) -> 50 | L10: =K10 -> 50
A11: Compte chèque BB | B11: Euros | C11: BoursoBank | D11: Euro | E11: EUR | F11: Barnabé | G11: non | H11: 45292 | I11: =SUMIFS(OPmontant,OPcompte,$A11,OPdevise,$E11,OPcatégorie,Solde,OPdate,$H11) -> 0 | J11: =_xlfn.MAXIFS(OPdate,OPcompte,$A11,OPdevise,$E11,OPcatégorie,Solde) -> 0 | K11: =SUMIFS(OPmontant,OPcompte,$A11,OPdevise,$E11,OPcatégorie,Solde,OPdate,$J11) -> 0 | L11: =K11 -> 0
A12: Compte chèque commun | B12: Euros | C12: Société Générale | D12: Euro | E12: EUR | F12: Commun | G12: non | H12: 28126 | I12: =SUMIFS(OPmontant,OPcompte,$A12,OPdevise,$E12,OPcatégorie,Solde,OPdate,$H12) -> 0 | J12: =_xlfn.MAXIFS(OPdate,OPcompte,$A12,OPdevise,$E12,OPcatégorie,Solde) -> 46092 | K12: =SUMIFS(OPmontant,OPcompte,$A12,OPdevise,$E12,OPcatégorie,Solde,OPdate,$J12) -> 2881.92 | L12: =K12 -> 2881.92
A13: Espèces | B13: Euros | C13: Maison | D13: Euro | E13: EUR | F13: Commun | G13: oui | H13: =_xlfn.MINIFS(OPdate,OPcompte,$A13,OPdevise,$E13,OPcatégorie,Solde) -> 45657 | I13: =SUMIFS(OPmontant,OPcompte,$A13,OPdevise,$E13,OPcatégorie,Solde,OPdate,$H13) -> 2500 | J13: =_xlfn.MAXIFS(OPdate,OPcompte,$A13,OPdevise,$E13,OPcatégorie,Solde) -> 46084 | K13: =SUMIFS(OPmontant,OPcompte,$A13,OPdevise,$E13,OPcatégorie,Solde,OPdate,$J13) -> 7 | L13: =K13 -> 7
A14: Livret A Barnabé | B14: Euros | C14: Société Générale | D14: Euro | E14: EUR | F14: Barnabé | G14: non | H14: =_xlfn.MINIFS(OPdate,OPcompte,$A14,OPdevise,$E14,OPcatégorie,Solde) -> 0 | I14: =SUMIFS(OPmontant,OPcompte,$A14,OPdevise,$E14,OPcatégorie,Solde,OPdate,$H14) -> 0 | J14: =_xlfn.MAXIFS(OPdate,OPcompte,$A14,OPdevise,$E14,OPcatégorie,Solde) -> 0 | K14: =SUMIFS(OPmontant,OPcompte,$A14,OPdevise,$E14,OPcatégorie,Solde,OPdate,$J14) -> 0 | L14: =K14 -> 0
A15: Compte Paypal | B15: Euros | C15: Paypal | D15: Euro | E15: EUR | F15: Barnabé | G15: non | H15: =_xlfn.MINIFS(OPdate,OPcompte,$A15,OPdevise,$E15,OPcatégorie,Solde) -> 46091 | I15: =SUMIFS(OPmontant,OPcompte,$A15,OPdevise,$E15,OPcatégorie,Solde,OPdate,$H15) -> 10 | J15: =_xlfn.MAXIFS(OPdate,OPcompte,$A15,OPdevise,$E15,OPcatégorie,Solde) -> 46091 | K15: =SUMIFS(OPmontant,OPcompte,$A15,OPdevise,$E15,OPcatégorie,Solde,OPdate,$J15) -> 10 | L15: =K15 -> 10
A16: Compte Wise EUR | B16: Euros | C16: Wise | D16: Euro | E16: EUR | F16: Barnabé | G16: non | H16: 45627 | I16: =SUMIFS(OPmontant,OPcompte,$A16,OPdevise,$E16,OPcatégorie,Solde,OPdate,$H16) -> 0 | J16: =_xlfn.MAXIFS(OPdate,OPcompte,$A16,OPdevise,$E16,OPcatégorie,Solde) -> 0 | K16: =SUMIFS(OPmontant,OPcompte,$A16,OPdevise,$E16,OPcatégorie,Solde,OPdate,$J16) -> 0 | L16: =K16 -> 0
A17: Portefeuille DEGIRO Réserve | B17: Euros | C17: DEGIRO | D17: Euro | E17: EUR | F17: Barnabé | G17: non | H17: =_xlfn.MINIFS(OPdate,OPcompte,$A17,OPdevise,$E17,OPcatégorie,Solde) -> 0 | I17: =SUMIFS(OPmontant,OPcompte,$A17,OPdevise,$E17,OPcatégorie,Solde,OPdate,$H17) -> 0 | J17: =_xlfn.MAXIFS(OPdate,OPcompte,$A17,OPdevise,$E17,OPcatégorie,Solde) -> 0 | K17: =SUMIFS(OPmontant,OPcompte,$A17,OPdevise,$E17,OPcatégorie,Solde,OPdate,$J17) -> 0 | L17: =K17 -> 0
A18: Portefeuille BB Réserve | B18: Euros | C18: BoursoBank | D18: Euro | E18: EUR | F18: Barnabé | G18: non | H18: =_xlfn.MINIFS(OPdate,OPcompte,$A18,OPdevise,$E18,OPcatégorie,Solde) -> 0 | I18: =SUMIFS(OPmontant,OPcompte,$A18,OPdevise,$E18,OPcatégorie,Solde,OPdate,$H18) -> 0 | J18: =_xlfn.MAXIFS(OPdate,OPcompte,$A18,OPdevise,$E18,OPcatégorie,Solde) -> 0 | K18: =SUMIFS(OPmontant,OPcompte,$A18,OPdevise,$E18,OPcatégorie,Solde,OPdate,$J18) -> 0 | L18: =K18 -> 0
A19: Compte Wise USD | B19: Devises étrangères | C19: Wise | D19: Dollar US | E19: USD | F19: Barnabé | G19: non | H19: 45653 | I19: =SUMIFS(OPmontant,OPcompte,$A19,OPdevise,$E19,OPcatégorie,Solde,OPdate,$H19) -> 0 | J19: =_xlfn.MAXIFS(OPdate,OPcompte,$A19,OPdevise,$E19,OPcatégorie,Solde) -> 0 | K19: =SUMIFS(OPmontant,OPcompte,$A19,OPdevise,$E19,OPcatégorie,Solde,OPdate,$J19) -> 0 | L19: =K19*cours_USD -> 0
A20: Compte Wise SGD | B20: Devises étrangères | C20: Wise | D20: Dollar Singapour | E20: SGD | F20: Barnabé | G20: non | H20: 45631 | I20: =SUMIFS(OPmontant,OPcompte,$A20,OPdevise,$E20,OPcatégorie,Solde,OPdate,$H20) -> 0 | J20: =_xlfn.MAXIFS(OPdate,OPcompte,$A20,OPdevise,$E20,OPcatégorie,Solde) -> 0 | K20: =SUMIFS(OPmontant,OPcompte,$A20,OPdevise,$E20,OPcatégorie,Solde,OPdate,$J20) -> 0 | L20: =K20*cours_SGD -> 0
A21: Portefeuille eToro USD Réserve | B21: Devises étrangères | C21: eToro | D21: Dollar US | E21: USD | F21: Barnabé | G21: non | H21: =_xlfn.MINIFS(OPdate,OPcompte,$A21,OPdevise,$E21,OPcatégorie,Solde) -> 45621 | I21: =SUMIFS(OPmontant,OPcompte,$A21,OPdevise,$E21,OPcatégorie,Solde,OPdate,$H21) -> 2500 | J21: =_xlfn.MAXIFS(OPdate,OPcompte,$A21,OPdevise,$E21,OPcatégorie,Solde) -> 46050 | K21: =SUMIFS(OPmontant,OPcompte,$A21,OPdevise,$E21,OPcatégorie,Solde,OPdate,$J21) -> 487.59 | L21: =K21*cours_USD -> 421.03397
A22: Créance Francine | B22: Créances | C22: Francine | D22: Euro | E22: EUR | F22: Commun | G22: non | H22: 42873 | I22: 156270 | J22: =_xlfn.MAXIFS(OPdate,OPcompte,$A22,OPdevise,$E22,OPcatégorie,Solde) -> 46058 | K22: =SUMIFS(OPmontant,OPcompte,$A22,OPdevise,$E22,OPcatégorie,Solde,OPdate,$J22) -> 9965 | L22: =K22 -> 9965
A23: BlueWallet BTC | B23: Crypto monnaies | C23: Blockchain | D23: Bitcoin | E23: SAT | F23: Commun | G23: oui | H23: 44967 | I23: =SUMIFS(OPmontant,OPcompte,$A23,OPdevise,$E23,OPcatégorie,Solde,OPdate,$H23) -> 0 | J23: =_xlfn.MAXIFS(OPdate,OPcompte,$A23,OPdevise,$E23,OPcatégorie,Solde) -> 45292 | K23: =SUMIFS(OPmontant,OPcompte,$A23,OPdevise,$E23,OPcatégorie,Solde,OPdate,$J23) -> 0 | L23: =K23*cours_SAT -> 0
A24: Phoenix Lightning BTC | B24: Crypto monnaies | C24: Blockchain | D24: Bitcoin | E24: SAT | F24: Commun | G24: oui | H24: 44967 | I24: =SUMIFS(OPmontant,OPcompte,$A24,OPdevise,$E24,OPcatégorie,Solde,OPdate,$H24) -> 0 | J24: =_xlfn.MAXIFS(OPdate,OPcompte,$A24,OPdevise,$E24,OPcatégorie,Solde) -> 45292 | K24: =SUMIFS(OPmontant,OPcompte,$A24,OPdevise,$E24,OPcatégorie,Solde,OPdate,$J24) -> 278800 | L24: =K24*cours_SAT -> 170.09309
A25: Compte Kraken BTC | B25: Crypto monnaies | C25: Kraken | D25: Bitcoin | E25: SAT | F25: Commun | G25: non | H25: 45855 | I25: =SUMIFS(OPmontant,OPcompte,$A25,OPdevise,$E25,OPcatégorie,Solde,OPdate,$H25) -> 0 | J25: =_xlfn.MAXIFS(OPdate,OPcompte,$A25,OPdevise,$E25,OPcatégorie,Solde) -> 45967 | K25: =SUMIFS(OPmontant,OPcompte,$A25,OPdevise,$E25,OPcatégorie,Solde,OPdate,$J25) -> 51277 | L25: =K25*cours_SAT -> 31.283585
A26: Cake Wallet XMR | B26: Crypto monnaies | C26: Blockchain | D26: Monero | E26: XMR | F26: Commun | G26: oui | H26: 44999 | I26: =SUMIFS(OPmontant,OPcompte,$A26,OPdevise,$E26,OPcatégorie,Solde,OPdate,$H26) -> 0 | J26: =_xlfn.MAXIFS(OPdate,OPcompte,$A26,OPdevise,$E26,OPcatégorie,Solde) -> 0 | K26: =SUMIFS(OPmontant,OPcompte,$A26,OPdevise,$E26,OPcatégorie,Solde,OPdate,$J26) -> 0 | L26: =K26*cours_XMR -> 0
A27: Pièces or | B27: Biens matériels | C27: Coffre | D27: Mobilier | E27: OrPr | F27: Commun | G27: oui | H27: 45048 | I27: =SUMIFS(OPmontant,OPcompte,$A27,OPdevise,$E27,OPcatégorie,Solde,OPdate,$H27) -> 0 | J27: =_xlfn.MAXIFS(OPdate,OPcompte,$A27,OPdevise,$E27,OPcatégorie,Solde) -> 45457 | K27: =SUMIFS(OPmontant,OPcompte,$A27,OPdevise,$E27,OPcatégorie,Solde,OPdate,$J27) -> 14.09344 | L27: =K27*cours_OrPr -> 2118.4859
A28: Maison | B28: Biens matériels | C28: Maison | D28: Foncier | F28: Commun | G28: oui | H28: 43750 | I28: 200000 | K28: 100000 | L28: =K28 -> 100000
A29: Auto | B29: Biens matériels | C29: Auto | D29: Mobilier | F29: Commun | G29: oui | H29: 37773 | I29: 30000 | K29: 9000 | L29: =K29 -> 9000
A30: Mobilier maison | B30: Biens matériels | C30: Maison | D30: Mobilier | F30: Commun | G30: oui | K30: 15000 | L30: =K30 -> 15000
A31: ⚓
A32: Total | L32: =ROUND(SUM(AVRmontant_solde_euro),2) -> 142580.98

Sheet Budget
A1: =Contrôles!K$52 -> ✓ | C1: =C$2-365 -> 45913
C2: =TODAY() -> 46278
A3: Dépenses et revenus | B3: Type | C3: Année glissante
A4: ⚓
A5: Divers | B5: Fixe | C5: =SUMIF(CATposte,A5,CATaffectation) -> -9.29126
A6: Produits financiers | B6: Fixe | C6: =SUMIF(CATposte,A6,CATaffectation) -> 9.01494
A7: Loisirs et restaurant | B7: Fixe | C7: =SUMIF(CATposte,A7,CATaffectation) -> -120
A8: Santé | B8: Fixe | C8: =SUMIF(CATposte,A8,CATaffectation) -> 0
A9: Maison | B9: Fixe | C9: =SUMIF(CATposte,A9,CATaffectation) -> -1670
A10: ⚓
A11: Total = épargne | C11: =SUM(POSTESmontant) -> -1790.2763
A12: Epargne fixe | C12: =SUMIF(POSTEStype,"Fixe",POSTESmontant) -> -1790.2763
A13: Epargne fixe / mois | C13: =C$12/12 -> -149.18969
A14: Écart avec tableau Affectation | C14: =ROUND(C$11-I$39,2) -> 0
E16: CATÉGORIES
E17: Catégories d’opérations | F17: EUR | G17: Total € au cours du jour | H17: Affectation % | I17: Affectation | J17: Dépenses et revenus
E18: (année glissante) | F18: =INDEX(COTcours,MATCH($F$17,COTcode,0)) -> 1
E19: ⚓
E20: @Change | F20: =SUMIFS(OPmontant,OPdevise,F$17,OPcatégorie,$E20,OPdate,">"&$C$2-365) -> -1018.08 | G20: =SUMPRODUCT(SUMIFS(OPmontant,OPcatégorie,$E20,OPdate,">"&$C$2-365,OPdevise,COTcode)*COTcours) -> 8.630135
E21: @Achat métaux | F21: =SUMIFS(OPmontant,OPdevise,F$17,OPcatégorie,$E21,OPdate,">"&$C$2-365) -> 0 | G21: =SUMPRODUCT(SUMIFS(OPmontant,OPcatégorie,$E21,OPdate,">"&$C$2-365,OPdevise,COTcode)*COTcours) -> 0
E22: @Virement | F22: =SUMIFS(OPmontant,OPdevise,F$17,OPcatégorie,$E22,OPdate,">"&$C$2-365) -> 0 | G22: =SUMPRODUCT(SUMIFS(OPmontant,OPcatégorie,$E22,OPdate,">"&$C$2-365,OPdevise,COTcode)*COTcours) -> 0
E23: @Achat titres | F23: =SUMIFS(OPmontant,OPdevise,F$17,OPcatégorie,$E23,OPdate,">"&$C$2-365) -> 0 | G23: =SUMPRODUCT(SUMIFS(OPmontant,OPcatégorie,$E23,OPdate,">"&$C$2-365,OPdevise,COTcode)*COTcours) -> 0
E24: @Vente titres | F24: =SUMIFS(OPmontant,OPdevise,F$17,OPcatégorie,$E24,OPdate,">"&$C$2-365) -> 0 | G24: =SUMPRODUCT(SUMIFS(OPmontant,OPcatégorie,$E24,OPdate,">"&$C$2-365,OPdevise,COTcode)*COTcours) -> 0
E25: @Arbitrage titres | F25: =SUMIFS(OPmontant,OPdevise,F$17,OPcatégorie,$E25,OPdate,">"&$C$2-365) -> 0 | G25: =SUMPRODUCT(SUMIFS(OPmontant,OPcatégorie,$E25,OPdate,">"&$C$2-365,OPdevise,COTcode)*COTcours) -> 0
E26: - | F26: =SUMIFS(OPmontant,OPdevise,F$17,OPcatégorie,$E26,OPdate,">"&$C$2-365) -> 0 | G26: =SUMPRODUCT(SUMIFS(OPmontant,OPcatégorie,$E26,OPdate,">"&$C$2-365,OPdevise,COTcode)*COTcours) -> 0 | H26: 1 | I26: =G26*H26 -> 0 | J26: Divers
E27: Ajustement | F27: =SUMIFS(OPmontant,OPdevise,F$17,OPcatégorie,$E27,OPdate,">"&$C$2-365) -> 0 | G27: =SUMPRODUCT(SUMIFS(OPmontant,OPcatégorie,$E27,OPdate,">"&$C$2-365,OPdevise,COTcode)*COTcours) -> -0.65626 | H27: 1 | I27: =G27*H27 -> -0.65626 | J27: Divers
E28: Coupon | F28: =SUMIFS(OPmontant,OPdevise,F$17,OPcatégorie,$E28,OPdate,">"&$C$2-365) -> 0 | G28: =SUMPRODUCT(SUMIFS(OPmontant,OPcatégorie,$E28,OPdate,">"&$C$2-365,OPdevise,COTcode)*COTcours) -> 9.01494 | H28: 1 | I28: =G28*H28 -> 9.01494 | J28: Produits financiers
E29: Frais bancaires | F29: =SUMIFS(OPmontant,OPdevise,F$17,OPcatégorie,$E29,OPdate,">"&$C$2-365) -> 0 | G29: =SUMPRODUCT(SUMIFS(OPmontant,OPcatégorie,$E29,OPdate,">"&$C$2-365,OPdevise,COTcode)*COTcours) -> -8.635 | H29: 1 | I29: =G29*H29 -> -8.635 | J29: Divers
E30: Intérêts | F30: =SUMIFS(OPmontant,OPdevise,F$17,OPcatégorie,$E30,OPdate,">"&$C$2-365) -> 0 | G30: =SUMPRODUCT(SUMIFS(OPmontant,OPcatégorie,$E30,OPdate,">"&$C$2-365,OPdevise,COTcode)*COTcours) -> 0 | H30: 1 | I30: =G30*H30 -> 0 | J30: Produits financiers
E31: Loisirs | F31: =SUMIFS(OPmontant,OPdevise,F$17,OPcatégorie,$E31,OPdate,">"&$C$2-365) -> -120 | G31: =SUMPRODUCT(SUMIFS(OPmontant,OPcatégorie,$E31,OPdate,">"&$C$2-365,OPdevise,COTcode)*COTcours) -> -120 | H31: 1 | I31: =G31*H31 -> -120 | J31: Loisirs et restaurant
E32: Maison | F32: =SUMIFS(OPmontant,OPdevise,F$17,OPcatégorie,$E32,OPdate,">"&$C$2-365) -> -1670 | G32: =SUMPRODUCT(SUMIFS(OPmontant,OPcatégorie,$E32,OPdate,">"&$C$2-365,OPdevise,COTcode)*COTcours) -> -1670 | H32: 1 | I32: =G32*H32 -> -1670 | J32: Maison
E33: Restaurant | F33: =SUMIFS(OPmontant,OPdevise,F$17,OPcatégorie,$E33,OPdate,">"&$C$2-365) -> 0 | G33: =SUMPRODUCT(SUMIFS(OPmontant,OPcatégorie,$E33,OPdate,">"&$C$2-365,OPdevise,COTcode)*COTcours) -> 0 | H33: 1 | I33: =G33*H33 -> 0 | J33: Loisirs et restaurant
E34: Santé | F34: =SUMIFS(OPmontant,OPdevise,F$17,OPcatégorie,$E34,OPdate,">"&$C$2-365) -> 0 | G34: =SUMPRODUCT(SUMIFS(OPmontant,OPcatégorie,$E34,OPdate,">"&$C$2-365,OPdevise,COTcode)*COTcours) -> 0 | H34: 1 | I34: =G34*H34 -> 0 | J34: Santé
E35: ⚓
E36: Total | F36: =SUM(CATmontant) -> -2808.08 | G36: =SUM(CATtotal_euro) -> -1781.6462
E37: Somme opérations | F37: =SUMIFS(OPmontant,OPdevise,F$17,OPdate,">"&$C$2-365,OPcatégorie,"<>"&Spéciale) -> -2808.08 | G37: =SUMPRODUCT(SUMIFS(OPmontant,OPdate,">"&$C$2-365,OPcatégorie,"<>"&Spéciale,OPdevise,COTcode)*COTcours) -> -1781.6462
E38: Écart | F38: =ROUND(F$36-F$37,2) -> 0 | G38: =ROUND(G$36-G$37,2) -> 0
E39: Total hors Changes et Virements | F39: =SUMIFS(CATmontant,CATnom,"<>@*") -> -1790 | G39: =SUMIFS(CATtotal_euro,CATnom,"<>@*") -> -1790.2763 | I39: =SUMIFS(CATaffectation,CATnom,"<>@*") -> -1790.2763
E40: Montant Euros | F40: =F$39*INDEX(COTcours,MATCH($F$17,COTcode,0)) -> -1790 | G40: =SUM(F$40) -> -1790

Sheet Plus_value
A1: =Contrôles!$K52 -> ✓ | B1: La plus value latente, PVL, est la différence entre la valorisation au cours du jour (SOLDE) et la somme des opérations passées aux cours d’époque (Montant initial + SIGMA).
B2: Le solde retenu d’un portefeuille correspond au plus récent entre cette feuille (détail des titres) et Opérations (#Solde global)
B3: =IF(OR(ISERROR(E53),ISERROR(K53)),"✗","✓") -> ✓ | E3: =E53 -> 1455.0078 | G3: =G53 -> 44927
A4: Section | B4: Compte | C4: Ligne | D4: Devise | E4: PVL | F4: PVL % | G4: Date initiale | H4: Montant initial | I4: SIGMA | J4: Date SOLDE | K4: SOLDE
A5: ⚓
A6: Les portefeuilles
A8: portefeuilles | B8: Assurance vie Alice | C8: Portefeuille
A9: portefeuilles | B9: Assurance vie Alice | C9: Total | D9: EUR | E9: =K9-(H9+I9) -> 0 | G9: 0 | H9: 0 | I9: 0 | K9: 0
A10: portefeuilles | B10: Assurance vie Alice | C10: #Solde Opérations | D10: EUR | E10: =K10-(H10+I10) -> 0 | G10: =_xlfn.MINIFS(OPdate,OPcompte,$B10,OPdevise,D10,OPcatégorie,Solde) -> 0 | H10: =SUMIFS(OPmontant,OPcompte,$B10,OPdevise,$D10,OPdate,$G10,OPcatégorie,Solde) -> 0 | I10: =I9 -> 0 | J10: =_xlfn.MAXIFS(OPdate,OPcompte,$B10,OPdevise,$D10,OPcatégorie,Solde) -> 0 | K10: =SUMIFS(OPmontant,OPcompte,$B10,OPdevise,$D10,OPcatégorie,Solde,OPdate,J10) -> 0
A11: portefeuilles | B11: Assurance vie Alice | C11: Retenu | D11: EUR | E11: =K11-(H11+I11) -> 0 | G11: =G10 -> 0 | H11: =H10 -> 0 | I11: =I10 -> 0 | J11: =IF(J9>J10,J9,J10) -> 0 | K11: =IF(J9>J10,K9,K10) -> 0
A13: portefeuilles | B13: PEE Alice | C13: Portefeuille
A14: portefeuilles | B14: PEE Alice | C14: Total | D14: EUR | E14: =K14-(H14+I14) -> 0 | G14: 0 | H14: 0 | I14: 0 | K14: 0
A15: portefeuilles | B15: PEE Alice | C15: #Solde Opérations | D15: EUR | E15: =K15-(H15+I15) -> 0 | G15: =_xlfn.MINIFS(OPdate,OPcompte,$B15,OPdevise,D15,OPcatégorie,Solde) -> 0 | H15: =SUMIFS(OPmontant,OPcompte,$B15,OPdevise,$D15,OPdate,$G15,OPcatégorie,Solde) -> 0 | I15: =I14 -> 0 | J15: =_xlfn.MAXIFS(OPdate,OPcompte,$B15,OPdevise,$D15,OPcatégorie,Solde) -> 0 | K15: =SUMIFS(OPmontant,OPcompte,$B15,OPdevise,$D15,OPcatégorie,Solde,OPdate,J15) -> 0
A16: portefeuilles | B16: PEE Alice | C16: Retenu | D16: EUR | E16: =K16-(H16+I16) -> 0 | G16: =G15 -> 0 | H16: =H15 -> 0 | I16: =I15 -> 0 | J16: =IF(J14>J15,J14,J15) -> 0 | K16: =IF(J14>J15,K14,K15) -> 0
A18: portefeuilles | B18: Portefeuille BB Titres | C18: Portefeuille
A19: portefeuilles | B19: Portefeuille BB Titres | C19: Total | D19: EUR | E19: =K19-(H19+I19) -> 0 | G19: 0 | H19: 0 | I19: 0 | K19: 0
A20: portefeuilles | B20: Portefeuille BB Titres | C20: #Solde Opérations | D20: EUR | E20: =K20-(H20+I20) -> 0 | G20: =_xlfn.MINIFS(OPdate,OPcompte,$B20,OPdevise,D20,OPcatégorie,Solde) -> 0 | H20: =SUMIFS(OPmontant,OPcompte,$B20,OPdevise,$D20,OPdate,$G20,OPcatégorie,Solde) -> 0 | I20: =I19 -> 0 | J20: =_xlfn.MAXIFS(OPdate,OPcompte,$B20,OPdevise,$D20,OPcatégorie,Solde) -> 0 | K20: =SUMIFS(OPmontant,OPcompte,$B20,OPdevise,$D20,OPcatégorie,Solde,OPdate,J20) -> 0
A21: portefeuilles | B21: Portefeuille BB Titres | C21: Retenu | D21: EUR | E21: =K21-(H21+I21) -> 0 | G21: =G20 -> 0 | H21: =H20 -> 0 | I21: =I20 -> 0 | J21: =IF(J19>J20,J19,J20) -> 0 | K21: =IF(J19>J20,K19,K20) -> 0
A23: portefeuilles | B23: Portefeuille DEGIRO Titres | C23: Portefeuille
A24: portefeuilles | B24: Portefeuille DEGIRO Titres | C24: Total | D24: EUR | E24: =K24-(H24+I24) -> 0 | G24: 0 | H24: 0 | I24: 0 | K24: 0
A25: portefeuilles | B25: Portefeuille DEGIRO Titres | C25: #Solde Opérations | D25: EUR | E25: =K25-(H25+I25) -> 0 | G25: =_xlfn.MINIFS(OPdate,OPcompte,$B25,OPdevise,D25,OPcatégorie,Solde) -> 0 | H25: =SUMIFS(OPmontant,OPcompte,$B25,OPdevise,$D25,OPdate,$G25,OPcatégorie,Solde) -> 0 | I25: =I24 -> 0 | J25: =_xlfn.MAXIFS(OPdate,OPcompte,$B25,OPdevise,$D25,OPcatégorie,Solde) -> 0 | K25: =SUMIFS(OPmontant,OPcompte,$B25,OPdevise,$D25,OPcatégorie,Solde,OPdate,J25) -> 0
A26: portefeuilles | B26: Portefeuille DEGIRO Titres | C26: Retenu | D26: EUR | E26: =K26-(H26+I26) -> 0 | G26: =G25 -> 0 | H26: =H25 -> 0 | I26: =I25 -> 0 | J26: =IF(J24>J25,J24,J25) -> 0 | K26: =IF(J24>J25,K24,K25) -> 0
A28: portefeuilles | B28: Portefeuille eToro USD Titres | C28: Portefeuille
A29: portefeuilles | B29: Portefeuille eToro USD Titres | C29: *AI.PA* | D29: USD | E29: =K29-(H29+I29) -> 2.62 | G29: 0 | H29: 10 | I29: =SUMIFS(OPmontant,OPcompte,$B29,OPdevise,$D29,OPcatégorie,"<>"&Spéciale,OPlibellé,$C29,OPdate,">="&$G29) -> 0 | J29: 46083 | K29: 12.62
A30: portefeuilles | B30: Portefeuille eToro USD Titres | C30: *SPX500* | D30: USD | E30: =K30-(H30+I30) -> -30.03 | G30: 45715 | H30: 0 | I30: =SUMIFS(OPmontant,OPcompte,$B30,OPdevise,$D30,OPcatégorie,"<>"&Spéciale,OPlibellé,$C30,OPdate,">="&$G30) -> 30.03 | J30: 45924 | K30: 0
A31: portefeuilles | B31: Portefeuille eToro USD Titres | C31: *BTC/USD* | D31: USD | E31: =K31-(H31+I31) -> -413.02 | G31: 45924 | H31: 0 | I31: =SUMIFS(OPmontant,OPcompte,$B31,OPdevise,$D31,OPcatégorie,"<>"&Spéciale,OPlibellé,$C31,OPdate,">="&$G31) -> 1000 | J31: 46083 | K31: 586.98
A32: portefeuilles | B32: Portefeuille eToro USD Titres | C32: *COMT* | D32: USD | E32: =K32-(H32+I32) -> 115.15 | G32: 46048 | H32: 0 | I32: =SUMIFS(OPmontant,OPcompte,$B32,OPdevise,$D32,OPcatégorie,"<>"&Spéciale,OPlibellé,$C32,OPdate,">="&$G32) -> 2491.99 | J32: 46083 | K32: 2607.14
A33: portefeuilles | B33: Portefeuille eToro USD Titres | C33: *KWEB* | D33: USD | E33: =K33-(H33+I33) -> -18.01 | G33: 45783 | H33: 0 | I33: =SUMIFS(OPmontant,OPcompte,$B33,OPdevise,$D33,OPcatégorie,"<>"&Spéciale,OPlibellé,$C33,OPdate,">="&$G33) -> 200 | J33: 46083 | K33: 181.99
A34: portefeuilles | B34: Portefeuille eToro USD Titres | C34: Total | D34: USD | E34: =K34-(H34+I34) -> -343.29 | G34: =MIN(G29:G33) -> 0 | H34: =SUMPRODUCT(H29:H33*IFERROR(INDEX(COTcours,MATCH(D29:D33,COTcode,0)),1))/IFERROR(INDEX(COTcours,MATCH(D34,COTcode,0)),1) -> 10 | I34: =SUMPRODUCT(I29:I33*IFERROR(INDEX(COTcours,MATCH(D29:D33,COTcode,0)),1))/IFERROR(INDEX(COTcours,MATCH(D34,COTcode,0)),1) -> 3722.02 | J34: =J33 -> 46083 | K34: =SUMPRODUCT(K29:K33*IFERROR(INDEX(COTcours,MATCH(D29:D33,COTcode,0)),1))/IFERROR(INDEX(COTcours,MATCH(D34,COTcode,0)),1) -> 3388.73
A35: portefeuilles | B35: Portefeuille eToro USD Titres | C35: #Solde Opérations | D35: USD | E35: =K35-(H35+I35) -> -3722.02 | G35: =_xlfn.MINIFS(OPdate,OPcompte,$B35,OPdevise,D35,OPcatégorie,Solde) -> 46050 | H35: =SUMIFS(OPmontant,OPcompte,$B35,OPdevise,$D35,OPdate,$G35,OPcatégorie,Solde) -> 3549.43 | I35: =I34 -> 3722.02 | J35: =_xlfn.MAXIFS(OPdate,OPcompte,$B35,OPdevise,$D35,OPcatégorie,Solde) -> 46050 | K35: =SUMIFS(OPmontant,OPcompte,$B35,OPdevise,$D35,OPcatégorie,Solde,OPdate,J35) -> 3549.43
A36: portefeuilles | B36: Portefeuille eToro USD Titres | C36: Retenu | D36: USD | E36: =K36-(H36+I36) -> -3882.72 | G36: =G35 -> 46050 | H36: =H35 -> 3549.43 | I36: =I35 -> 3722.02 | J36: =IF(J34>J35,J34,J35) -> 46083 | K36: =IF(J34>J35,K34,K35) -> 3388.73
A38: Les métaux
A39: métaux | B39: Pièces or | D39: OrPr | E39: =K39-(H39+I39) -> 2118.4859 | G39: =_xlfn.MINIFS(OPdate,OPcompte,B39,OPdevise,D39,OPcatégorie,Solde) -> 45457 | H39: =SUMIFS(OPequiv_euro,OPcompte,B39,OPdevise,D39,OPcatégorie,Solde,OPdate,G39) -> 0 | I39: =SUMIFS(OPequiv_euro,OPcompte,B39,OPdevise,D39,OPcatégorie,"<>"&Spéciale,OPdate,">="&G39) -> 0 | J39: =SUMIF(AVRintitulé,$B39,AVRdate_solde) -> 45457 | K39: =SUMIF(AVRintitulé,$B39,AVRmontant_solde_euro) -> 2118.4859
A41: Les cryptos
A42: crypto | B42: BlueWallet BTC | D42: SAT | E42: =K42-(H42+I42) -> 100 | G42: =_xlfn.MINIFS(OPdate,OPcompte,B42,OPdevise,D42,OPcatégorie,Solde) -> 44927 | H42: =SUMIFS(OPequiv_euro,OPcompte,B42,OPdevise,D42,OPcatégorie,Solde,OPdate,G42) -> 0 | I42: =SUMIFS(OPequiv_euro,OPcompte,B42,OPdevise,D42,OPcatégorie,"<>"&Spéciale,OPdate,">="&G42) -> -100 | J42: =SUMIF(AVRintitulé,$B42,AVRdate_solde) -> 45292 | K42: =SUMIF(AVRintitulé,$B42,AVRmontant_solde_euro) -> 0
A43: crypto | B43: Phoenix Lightning BTC | D43: SAT | E43: =K43-(H43+I43) -> 170.09309 | G43: =_xlfn.MINIFS(OPdate,OPcompte,B43,OPdevise,D43,OPcatégorie,Solde) -> 45292 | H43: =SUMIFS(OPequiv_euro,OPcompte,B43,OPdevise,D43,OPcatégorie,Solde,OPdate,G43) -> 0 | I43: =SUMIFS(OPequiv_euro,OPcompte,B43,OPdevise,D43,OPcatégorie,"<>"&Spéciale,OPdate,">="&G43) -> 0 | J43: =SUMIF(AVRintitulé,$B43,AVRdate_solde) -> 45292 | K43: =SUMIF(AVRintitulé,$B43,AVRmontant_solde_euro) -> 170.09309
A44: crypto | B44: Compte Kraken BTC | D44: SAT | E44: =K44-(H44+I44) -> 31.283585 | G44: =_xlfn.MINIFS(OPdate,OPcompte,B44,OPdevise,D44,OPcatégorie,Solde) -> 45923 | H44: =SUMIFS(OPequiv_euro,OPcompte,B44,OPdevise,D44,OPcatégorie,Solde,OPdate,G44) -> 0 | I44: =SUMIFS(OPequiv_euro,OPcompte,B44,OPdevise,D44,OPcatégorie,"<>"&Spéciale,OPdate,">="&G44) -> 0 | J44: =SUMIF(AVRintitulé,$B44,AVRdate_solde) -> 45967 | K44: =SUMIF(AVRintitulé,$B44,AVRmontant_solde_euro) -> 31.283585
A45: crypto | B45: Cake Wallet XMR | D45: XMR | E45: =K45-(H45+I45) -> 0 | G45: =_xlfn.MINIFS(OPdate,OPcompte,B45,OPdevise,D45,OPcatégorie,Solde) -> 0 | H45: =SUMIFS(OPequiv_euro,OPcompte,B45,OPdevise,D45,OPcatégorie,Solde,OPdate,G45) -> 0 | I45: =SUMIFS(OPequiv_euro,OPcompte,B45,OPdevise,D45,OPcatégorie,"<>"&Spéciale,OPdate,">="&G45) -> 0 | J45: =SUMIF(AVRintitulé,$B45,AVRdate_solde) -> 0 | K45: =SUMIF(AVRintitulé,$B45,AVRmontant_solde_euro) -> 0
A47: Les devises
A48: devises | B48: Compte Wise USD | D48: USD | E48: =K48-(H48+I48) -> 0 | G48: =_xlfn.MINIFS(OPdate,OPcompte,B48,OPdevise,D48,OPcatégorie,Solde) -> 0 | H48: =SUMIFS(OPequiv_euro,OPcompte,B48,OPdevise,D48,OPcatégorie,Solde,OPdate,G48) -> 0 | I48: =SUMIFS(OPequiv_euro,OPcompte,B48,OPdevise,D48,OPcatégorie,"<>"&Spéciale,OPdate,">="&G48) -> 0 | J48: =SUMIF(AVRintitulé,$B48,AVRdate_solde) -> 0 | K48: =SUMIF(AVRintitulé,$B48,AVRmontant_solde_euro) -> 0
...

Sheet Opérations
A1: Aujourd‘hui | F1: Compteur Réf.
A2: =TODAY() -> 46278 | B2: =Contrôles!K$52 -> ✓ | F2: 0 | G2: ="Opérations : "&COUNTIF(OPdate,"<"&DATE(année_courante,12,31)) -> Opérations : 70
A3: Date | B3: Libellé | C3: Montant | D3: Devise | E3: Eq. € | F3: Réf. | G3: Catégorie | H3: Compte | I3: Commentaire
A4: ⚓
A5: 44927 | B5: Relevé compte | C5: 503110 | D5: SAT | G5: #Solde | H5: BlueWallet BTC | I5: SAT = 1 / 100 000 000 Bitcoin
A6: 44927 | B6: Relevé compte | C6: 5000 | D6: EUR | G6: #Solde | H6: Compte chèque commun
A7: 44968 | B7: Transfert bitcoin -> lightning | C7: -280000 | D7: SAT | E7: -50 | F7: V1 | G7: @Virement | H7: BlueWallet BTC
A8: 44968 | B8: Id | C8: -584 | D8: SAT | G8: Frais bancaires | H8: BlueWallet BTC
A9: 44983 | B9: Id | C9: 280000 | D9: SAT | E9: 50 | F9: V1 | G9: @Virement | H9: Phoenix Lightning BTC
A10: 44983 | B10: Id | C10: -1200 | D10: SAT | G10: Frais bancaires | H10: Phoenix Lightning BTC
A11: 45000 | B11: Achat carte cadeau Amazon | C11: -218292 | D11: SAT | E11: -50 | F11: eur2 | G11: @Change | H11: BlueWallet BTC
A12: 45000 | B12: Id | C12: -4234 | D12: SAT | G12: Frais bancaires | H12: BlueWallet BTC
A13: 45000 | B13: Id | C13: 50 | D13: EUR | E13: 50 | F13: eur2 | G13: @Change | H13: Compte Amazon
A14: 45048 | B14: CMA | C14: 14.09344 | D14: OrPr | E14: 990 | F14: OrPr3 | G14: @Change | H14: Pièces or
A15: 45048 | B15: Commission CMA | C15: -39.6 | D15: EUR | G15: #Info | H15: Pièces or | I15: Opération non comptabilisée
A16: 45048 | B16: VIR. LOGITEL | C16: -990 | D16: EUR | E16: -990 | F16: OrPr3 | G16: @Change | H16: Compte chèque commun
A17: 45292 | B17: Relevé compte | C17: 0 | D17: SAT | G17: #Solde | H17: BlueWallet BTC
A18: 45292 | B18: Relevé compte | C18: 278800 | D18: SAT | G18: #Solde | H18: Phoenix Lightning BTC
A19: 45457 | B19: Relevé compte | C19: 14.09344 | D19: OrPr | G19: #Solde | H19: Pièces or
A20: 45621 | B20: Relevé compte | C20: 2500 | D20: USD | G20: #Solde | H20: Portefeuille eToro USD Réserve
A21: 45622 | B21: Action Air Liquide offert | C21: 10 | D21: USD | E21: 9.6 | G21: Intérêts | H21: Portefeuille eToro USD Titres
A22: 45657 | B22: Relevé compte | C22: 50 | D22: EUR | G22: #Solde | H22: Compte Amazon
A23: 45657 | B23: Relevé compte | C23: 10965 | D23: EUR | G23: #Solde | H23: Créance Francine
A24: 45657 | B24: Relevé compte | C24: 2500 | D24: EUR | G24: #Solde | H24: Espèces
A25: 45661 | B25: Nettoyage | C25: -1000 | D25: EUR | G25: Maison | H25: Espèces
A26: 45663 | B26: VIR. LOGITEL | C26: 500 | D26: EUR | F26: V4 | G26: @Virement | H26: Compte chèque commun
A27: 45663 | C27: -500 | D27: EUR | F27: V4 | G27: @Virement | H27: Créance Francine
A28: 45679 | B28: Ramonage | C28: -180 | D28: EUR | G28: Maison | H28: Espèces
A29: 45705 | B29: retrait DAB | C29: -300 | D29: EUR | F29: V5 | G29: @Virement | H29: Compte chèque commun
A30: 45705 | B30: retrait DAB | C30: 300 | D30: EUR | F30: V5 | G30: @Virement | H30: Espèces
A31: 45715 | B31: VIR. LOGITEL | C31: -500 | D31: EUR | E31: -500 | F31: usd6 | G31: @Change | H31: Compte chèque commun
A32: 45715 | B32: Dépôt | C32: 520.1 | D32: USD | E32: 500 | F32: usd6 | G32: @Change | H32: Portefeuille eToro USD Réserve
A33: 45715 | B33: Position ouverte SPX500/USD | C33: 60 | D33: USD | E33: 57.25 | F33: V7 | G33: @Achat titres | H33: Portefeuille eToro USD Titres
A34: 45715 | B34: Position ouverte SPX500/USD | C34: -60 | D34: USD | E34: -57.25 | F34: V7 | G34: @Achat titres | H34: Portefeuille eToro USD Réserve
A35: 45716 | B35: Bénéfice/Perte du trade SPX500/USD | C35: -29.97 | D35: USD | E35: -28.85 | F35: t8 | G35: @Vente titres | H35: Portefeuille eToro USD Titres
A36: 45716 | B36: Bénéfice/Perte du trade SPX500/USD | C36: 29.97 | D36: USD | E36: 28.85 | F36: t8 | G36: @Vente titres | H36: Portefeuille eToro USD Réserve
A37: 45716 | B37: Ajustement du prix de l’indice SPX500/USD | C37: 0.15 | D37: USD | G37: Ajustement | H37: Portefeuille eToro USD Réserve
A38: 45715 | B38: Frais overnight Quotidien | C38: -0.29 | D38: USD | G38: Frais bancaires | H38: Portefeuille eToro USD Réserve
A39: 45763 | C39: -33 | D39: EUR | G39: Restaurant | H39: Espèces
A40: 45783 | B40: Position ouverte KWEB/USD | C40: 200 | D40: USD | E40: 176 | G40: @Achat titres | H40: Portefeuille eToro USD Titres
...

Sheet Contrôles
A1: =$K$52 -> ✓
A2: Compte | B2: Devise | C2: Date ancrage | D2: Date relevé | E2: Montant ancrage | F2: Solde calculé | G2: Montant relevé | H2: Écart | I2: Contrôle écart
A3: ⚓
A4: =Avoirs!A5 -> Assurance vie Alice | B4: EUR | C4: =IF(COUNTIFS(OPcompte,$A4,OPdevise,$B4,OPcatégorie,Solde)>=2,_xlfn.MINIFS(OPdate,OPcompte,$A4,OPdevise,$B4,OPcatégorie,Solde),0) -> 0 | D4: =_xlfn.MAXIFS(OPdate,OPcompte,$A4,OPdevise,$B4,OPcatégorie,Solde) -> 0 | E4: =IF($C4=0,0,_xlfn.XLOOKUP(1,(OPcompte=$A4)*(OPdevise=$B4)*(OPcatégorie=Solde)*(OPdate=$C4),OPmontant,0,0,1)) -> 0 | F4: =$E4+SUMIFS(OPmontant,OPcompte,$A4,OPdevise,$B4,OPdate,">"&$C4,OPdate,"<="&$D4,OPcatégorie,"<>Solde",OPcatégorie,"<>"&Spéciale) -> 0 | G4: =_xlfn.XLOOKUP(1,(OPcompte=$A4)*(OPdevise=$B4)*(OPcatégorie=Solde)*(OPdate=$D4),OPmontant,0,0,-1) -> 0 | H4: =IF(ABS($G4-$F4)<0.015,0,ROUND($G4-$F4,2)) -> 0 | I4: Non
A5: =Avoirs!A6 -> PEE Alice | B5: EUR | C5: =IF(COUNTIFS(OPcompte,$A5,OPdevise,$B5,OPcatégorie,Solde)>=2,_xlfn.MINIFS(OPdate,OPcompte,$A5,OPdevise,$B5,OPcatégorie,Solde),0) -> 0 | D5: =_xlfn.MAXIFS(OPdate,OPcompte,$A5,OPdevise,$B5,OPcatégorie,Solde) -> 0 | E5: =IF($C5=0,0,_xlfn.XLOOKUP(1,(OPcompte=$A5)*(OPdevise=$B5)*(OPcatégorie=Solde)*(OPdate=$C5),OPmontant,0,0,1)) -> 0 | F5: =$E5+SUMIFS(OPmontant,OPcompte,$A5,OPdevise,$B5,OPdate,">"&$C5,OPdate,"<="&$D5,OPcatégorie,"<>Solde",OPcatégorie,"<>"&Spéciale) -> 0 | G5: =_xlfn.XLOOKUP(1,(OPcompte=$A5)*(OPdevise=$B5)*(OPcatégorie=Solde)*(OPdate=$D5),OPmontant,0,0,-1) -> 0 | H5: =IF(ABS($G5-$F5)<0.015,0,ROUND($G5-$F5,2)) -> 0 | I5: Non
A6: =Avoirs!A7 -> Portefeuille BB Titres | B6: EUR | C6: =IF(COUNTIFS(OPcompte,$A6,OPdevise,$B6,OPcatégorie,Solde)>=2,_xlfn.MINIFS(OPdate,OPcompte,$A6,OPdevise,$B6,OPcatégorie,Solde),0) -> 0 | D6: =_xlfn.MAXIFS(OPdate,OPcompte,$A6,OPdevise,$B6,OPcatégorie,Solde) -> 0 | E6: =IF($C6=0,0,_xlfn.XLOOKUP(1,(OPcompte=$A6)*(OPdevise=$B6)*(OPcatégorie=Solde)*(OPdate=$C6),OPmontant,0,0,1)) -> 0 | F6: =$E6+SUMIFS(OPmontant,OPcompte,$A6,OPdevise,$B6,OPdate,">"&$C6,OPdate,"<="&$D6,OPcatégorie,"<>Solde",OPcatégorie,"<>"&Spéciale) -> 0 | G6: =_xlfn.XLOOKUP(1,(OPcompte=$A6)*(OPdevise=$B6)*(OPcatégorie=Solde)*(OPdate=$D6),OPmontant,0,0,-1) -> 0 | H6: =IF(ABS($G6-$F6)<0.015,0,ROUND($G6-$F6,2)) -> 0 | I6: Non
A7: =Avoirs!A8 -> Portefeuille DEGIRO Titres | B7: EUR | C7: =IF(COUNTIFS(OPcompte,$A7,OPdevise,$B7,OPcatégorie,Solde)>=2,_xlfn.MINIFS(OPdate,OPcompte,$A7,OPdevise,$B7,OPcatégorie,Solde),0) -> 0 | D7: =_xlfn.MAXIFS(OPdate,OPcompte,$A7,OPdevise,$B7,OPcatégorie,Solde) -> 0 | E7: =IF($C7=0,0,_xlfn.XLOOKUP(1,(OPcompte=$A7)*(OPdevise=$B7)*(OPcatégorie=Solde)*(OPdate=$C7),OPmontant,0,0,1)) -> 0 | F7: =$E7+SUMIFS(OPmontant,OPcompte,$A7,OPdevise,$B7,OPdate,">"&$C7,OPdate,"<="&$D7,OPcatégorie,"<>Solde",OPcatégorie,"<>"&Spéciale) -> 0 | G7: =_xlfn.XLOOKUP(1,(OPcompte=$A7)*(OPdevise=$B7)*(OPcatégorie=Solde)*(OPdate=$D7),OPmontant,0,0,-1) -> 0 | H7: =IF(ABS($G7-$F7)<0.015,0,ROUND($G7-$F7,2)) -> 0 | I7: Non
A8: =Avoirs!A9 -> Portefeuille eToro USD Titres | B8: USD | C8: =IF(COUNTIFS(OPcompte,$A8,OPdevise,$B8,OPcatégorie,Solde)>=2,_xlfn.MINIFS(OPdate,OPcompte,$A8,OPdevise,$B8,OPcatégorie,Solde),0) -> 0 | D8: =_xlfn.MAXIFS(OPdate,OPcompte,$A8,OPdevise,$B8,OPcatégorie,Solde) -> 46050 | E8: =IF($C8=0,0,_xlfn.XLOOKUP(1,(OPcompte=$A8)*(OPdevise=$B8)*(OPcatégorie=Solde)*(OPdate=$C8),OPmontant,0,0,1)) -> 0 | F8: =$E8+SUMIFS(OPmontant,OPcompte,$A8,OPdevise,$B8,OPdate,">"&$C8,OPdate,"<="&$D8,OPcatégorie,"<>Solde",OPcatégorie,"<>"&Spéciale) -> 3732.02 | G8: =_xlfn.XLOOKUP(1,(OPcompte=$A8)*(OPdevise=$B8)*(OPcatégorie=Solde)*(OPdate=$D8),OPmontant,0,0,-1) -> 3549.43 | H8: =IF(ABS($G8-$F8)<0.015,0,ROUND($G8-$F8,2)) -> -182.59 | I8: Non
A9: =Avoirs!A10 -> Compte Amazon | B9: EUR | C9: =IF(COUNTIFS(OPcompte,$A9,OPdevise,$B9,OPcatégorie,Solde)>=2,_xlfn.MINIFS(OPdate,OPcompte,$A9,OPdevise,$B9,OPcatégorie,Solde),0) -> 0 | D9: =_xlfn.MAXIFS(OPdate,OPcompte,$A9,OPdevise,$B9,OPcatégorie,Solde) -> 45657 | E9: =IF($C9=0,0,_xlfn.XLOOKUP(1,(OPcompte=$A9)*(OPdevise=$B9)*(OPcatégorie=Solde)*(OPdate=$C9),OPmontant,0,0,1)) -> 0 | F9: =$E9+SUMIFS(OPmontant,OPcompte,$A9,OPdevise,$B9,OPdate,">"&$C9,OPdate,"<="&$D9,OPcatégorie,"<>Solde",OPcatégorie,"<>"&Spéciale) -> 50 | G9: =_xlfn.XLOOKUP(1,(OPcompte=$A9)*(OPdevise=$B9)*(OPcatégorie=Solde)*(OPdate=$D9),OPmontant,0,0,-1) -> 50 | H9: =IF(ABS($G9-$F9)<0.015,0,ROUND($G9-$F9,2)) -> 0 | I9: Oui
A10: =Avoirs!A11 -> Compte chèque BB | B10: EUR | C10: =IF(COUNTIFS(OPcompte,$A10,OPdevise,$B10,OPcatégorie,Solde)>=2,_xlfn.MINIFS(OPdate,OPcompte,$A10,OPdevise,$B10,OPcatégorie,Solde),0) -> 0 | D10: =_xlfn.MAXIFS(OPdate,OPcompte,$A10,OPdevise,$B10,OPcatégorie,Solde) -> 0 | E10: =IF($C10=0,0,_xlfn.XLOOKUP(1,(OPcompte=$A10)*(OPdevise=$B10)*(OPcatégorie=Solde)*(OPdate=$C10),OPmontant,0,0,1)) -> 0 | F10: =$E10+SUMIFS(OPmontant,OPcompte,$A10,OPdevise,$B10,OPdate,">"&$C10,OPdate,"<="&$D10,OPcatégorie,"<>Solde",OPcatégorie,"<>"&Spéciale) -> 0 | G10: =_xlfn.XLOOKUP(1,(OPcompte=$A10)*(OPdevise=$B10)*(OPcatégorie=Solde)*(OPdate=$D10),OPmontant,0,0,-1) -> 0 | H10: =IF(ABS($G10-$F10)<0.015,0,ROUND($G10-$F10,2)) -> 0 | I10: Oui
A11: =Avoirs!A12 -> Compte chèque commun | B11: EUR | C11: =IF(COUNTIFS(OPcompte,$A11,OPdevise,$B11,OPcatégorie,Solde)>=2,_xlfn.MINIFS(OPdate,OPcompte,$A11,OPdevise,$B11,OPcatégorie,Solde),0) -> 44927 | D11: =_xlfn.MAXIFS(OPdate,OPcompte,$A11,OPdevise,$B11,OPcatégorie,Solde) -> 46092 | E11: =IF($C11=0,0,_xlfn.XLOOKUP(1,(OPcompte=$A11)*(OPdevise=$B11)*(OPcatégorie=Solde)*(OPdate=$C11),OPmontant,0,0,1)) -> 5000 | F11: =$E11+SUMIFS(OPmontant,OPcompte,$A11,OPdevise,$B11,OPdate,">"&$C11,OPdate,"<="&$D11,OPcatégorie,"<>Solde",OPcatégorie,"<>"&Spéciale) -> 2881.92 | G11: =_xlfn.XLOOKUP(1,(OPcompte=$A11)*(OPdevise=$B11)*(OPcatégorie=Solde)*(OPdate=$D11),OPmontant,0,0,-1) -> 2881.92 | H11: =IF(ABS($G11-$F11)<0.015,0,ROUND($G11-$F11,2)) -> 0 | I11: Oui
A12: =Avoirs!A13 -> Espèces | B12: EUR | C12: =IF(COUNTIFS(OPcompte,$A12,OPdevise,$B12,OPcatégorie,Solde)>=2,_xlfn.MINIFS(OPdate,OPcompte,$A12,OPdevise,$B12,OPcatégorie,Solde),0) -> 45657 | D12: =_xlfn.MAXIFS(OPdate,OPcompte,$A12,OPdevise,$B12,OPcatégorie,Solde) -> 46084 | E12: =IF($C12=0,0,_xlfn.XLOOKUP(1,(OPcompte=$A12)*(OPdevise=$B12)*(OPcatégorie=Solde)*(OPdate=$C12),OPmontant,0,0,1)) -> 2500 | F12: =$E12+SUMIFS(OPmontant,OPcompte,$A12,OPdevise,$B12,OPdate,">"&$C12,OPdate,"<="&$D12,OPcatégorie,"<>Solde",OPcatégorie,"<>"&Spéciale) -> 7 | G12: =_xlfn.XLOOKUP(1,(OPcompte=$A12)*(OPdevise=$B12)*(OPcatégorie=Solde)*(OPdate=$D12),OPmontant,0,0,-1) -> 7 | H12: =IF(ABS($G12-$F12)<0.015,0,ROUND($G12-$F12,2)) -> 0 | I12: Oui
A13: =Avoirs!A14 -> Livret A Barnabé | B13: EUR | C13: =IF(COUNTIFS(OPcompte,$A13,OPdevise,$B13,OPcatégorie,Solde)>=2,_xlfn.MINIFS(OPdate,OPcompte,$A13,OPdevise,$B13,OPcatégorie,Solde),0) -> 0 | D13: =_xlfn.MAXIFS(OPdate,OPcompte,$A13,OPdevise,$B13,OPcatégorie,Solde) -> 0 | E13: =IF($C13=0,0,_xlfn.XLOOKUP(1,(OPcompte=$A13)*(OPdevise=$B13)*(OPcatégorie=Solde)*(OPdate=$C13),OPmontant,0,0,1)) -> 0 | F13: =$E13+SUMIFS(OPmontant,OPcompte,$A13,OPdevise,$B13,OPdate,">"&$C13,OPdate,"<="&$D13,OPcatégorie,"<>Solde",OPcatégorie,"<>"&Spéciale) -> 0 | G13: =_xlfn.XLOOKUP(1,(OPcompte=$A13)*(OPdevise=$B13)*(OPcatégorie=Solde)*(OPdate=$D13),OPmontant,0,0,-1) -> 0 | H13: =IF(ABS($G13-$F13)<0.015,0,ROUND($G13-$F13,2)) -> 0 | I13: Oui
A14: =Avoirs!A15 -> Compte Paypal | B14: EUR | C14: =IF(COUNTIFS(OPcompte,$A14,OPdevise,$B14,OPcatégorie,Solde)>=2,_xlfn.MINIFS(OPdate,OPcompte,$A14,OPdevise,$B14,OPcatégorie,Solde),0) -> 0 | D14: =_xlfn.MAXIFS(OPdate,OPcompte,$A14,OPdevise,$B14,OPcatégorie,Solde) -> 46091 | E14: =IF($C14=0,0,_xlfn.XLOOKUP(1,(OPcompte=$A14)*(OPdevise=$B14)*(OPcatégorie=Solde)*(OPdate=$C14),OPmontant,0,0,1)) -> 0 | F14: =$E14+SUMIFS(OPmontant,OPcompte,$A14,OPdevise,$B14,OPdate,">"&$C14,OPdate,"<="&$D14,OPcatégorie,"<>Solde",OPcatégorie,"<>"&Spéciale) -> 10 | G14: =_xlfn.XLOOKUP(1,(OPcompte=$A14)*(OPdevise=$B14)*(OPcatégorie=Solde)*(OPdate=$D14),OPmontant,0,0,-1) -> 10 | H14: =IF(ABS($G14-$F14)<0.015,0,ROUND($G14-$F14,2)) -> 0 | I14: Oui
A15: =Avoirs!A16 -> Compte Wise EUR | B15: EUR | C15: =IF(COUNTIFS(OPcompte,$A15,OPdevise,$B15,OPcatégorie,Solde)>=2,_xlfn.MINIFS(OPdate,OPcompte,$A15,OPdevise,$B15,OPcatégorie,Solde),0) -> 0 | D15: =_xlfn.MAXIFS(OPdate,OPcompte,$A15,OPdevise,$B15,OPcatégorie,Solde) -> 0 | E15: =IF($C15=0,0,_xlfn.XLOOKUP(1,(OPcompte=$A15)*(OPdevise=$B15)*(OPcatégorie=Solde)*(OPdate=$C15),OPmontant,0,0,1)) -> 0 | F15: =$E15+SUMIFS(OPmontant,OPcompte,$A15,OPdevise,$B15,OPdate,">"&$C15,OPdate,"<="&$D15,OPcatégorie,"<>Solde",OPcatégorie,"<>"&Spéciale) -> 0 | G15: =_xlfn.XLOOKUP(1,(OPcompte=$A15)*(OPdevise=$B15)*(OPcatégorie=Solde)*(OPdate=$D15),OPmontant,0,0,-1) -> 0 | H15: =IF(ABS($G15-$F15)<0.015,0,ROUND($G15-$F15,2)) -> 0 | I15: Oui
... A25: =Avoirs!A26 -> Cake Wallet XMR | B25: XMR | C25: =IF(COUNTIFS(OPcompte,$A25,OPdevise,$B25,OPcatégorie,Solde)>=2,_xlfn.MINIFS(OPdate,OPcompte,$A25,OPdevise,$B25,OPcatégorie,Solde),0) -> 0 | D25: =_xlfn.MAXIFS(OPdate,OPcompte,$A25,OPdevise,$B25,OPcatégorie,Solde) -> 0 | E25: =IF($C25=0,0,_xlfn.XLOOKUP(1,(OPcompte=$A25)*(OPdevise=$B25)*(OPcatégorie=Solde)*(OPdate=$C25),OPmontant,0,0,1)) -> 0 | F25: =$E25+SUMIFS(OPmontant,OPcompte,$A25,OPdevise,$B25,OPdate,">"&$C25,OPdate,"<="&$D25,OPcatégorie,"<>Solde",OPcatégorie,"<>"&Spéciale) -> 0 | G25: =_xlfn.XLOOKUP(1,(OPcompte=$A25)*(OPdevise=$B25)*(OPcatégorie=Solde)*(OPdate=$D25),OPmontant,0,0,-1) -> 0 | H25: =IF(ABS($G25-$F25)<0.015,0,ROUND($G25-$F25,2)) -> 0 | I25: Oui
A26: ⚓
J29: CONTRÔLES
J30: Type de contrôle | K30: Affichage | L30: Général | M30: EUR
J31: ⚓
J32: COMPTES (de début #Solde à fin #Solde) | K32: =IF(L32=0,"✓","✗") -> ✓ | L32: =COUNTIFS(CTRL1controle,"Oui")-COUNTIFS(CTRL1controle,"Oui",CTRL1ecart,0) -> 0 | M32: =COUNTIFS(CTRL1devise,M$8,CTRL1controle,"Oui")-COUNTIFS(CTRL1devise,M$8,CTRL1controle,"Oui",CTRL1ecart,0) -> 0
J33: CATÉGORIES | K33: =IF(L33>0,"✗","✓") -> ✓ | L33: =IF(L34>0,1,0)+IF(L35>0,1,0)+IF(ABS(L36)>=1,1,0) -> 0
J34: Manquantes | L34: =SUMPRODUCT(ISNUMBER(OPdate)*(OPcatégorie="")) -> 0
J35: Inconnues | L35: =SUMPRODUCT((COUNTIF(CATnom,OPcatégorie)=0)*(OPcatégorie<>"")*(LEFT(OPcatégorie,1)<>"#")) -> 0
J36: Écart Budget € (année glissante) | L36: =ABS(Budget!G$38)+ABS(Budget!I$39-Budget!G$39)+ABS(Budget!C$14) -> 0 | M36: =ROUND(SUMPRODUCT(SUMIFS(OPmontant,OPdevise,M$30,OPcatégorie,CATnom,OPdate,">"&Budget!$C$2-365))-SUMIFS(OPmontant,OPdevise,M$30,OPcatégorie,"<>"&Spéciale,OPdate,">"&Budget!$C$2-365),2) -> 0
J37: DIVERS | K37: =IF(L37>0,"⚠","✓") -> ✓ | L37: =SUM(L38:L40) -> 0
J38: Date hors période | L38: =COUNTIF(OPdate,"<"&DATE(2020,1,1))+COUNTIF(OPdate,">"&DATE(année_courante,12,31)) -> 0
J39: Ventilation Patrimoine | L39: =Patrimoine!D54 -> 0
J40: Cotations | L40: =IF(Cotations!B27="⚠",1,0) -> 0
J41: APPARIEMENTS | K41: =IF(L41=0,"✓","⚠") -> ✓ | L41: =COUNTIFS(OPréf,"-") -> 0 | M41: =COUNTIFS(OPréf,"-",OPdevise,M$30) -> 0
J42: BALANCES | K42: =IF(L42=0,"✓","⚠") -> ✓ | L42: =3-COUNTIFS(L43:L45,0) -> 0 | M42: =COUNTA($J43:$J45)-COUNTIFS(M43:M45,0) -> 1
J43: Virements € | L43: =ROUND(SUMIFS(OPequiv_euro,OPcatégorie,"@Virement"),0) -> 0 | M43: =SUMIFS(OPequiv_euro,OPdevise,M$30,OPcatégorie,"@Virement") -> 0
J44: Titres € | L44: =ROUND(SUMIFS(OPequiv_euro,OPcatégorie,"*titres"),0) -> 0 | M44: =SUMIFS(OPequiv_euro,OPdevise,M$30,OPcatégorie,"*titres") -> 0
J45: Changes Eq € | L45: =ROUND(SUMIFS(OPequiv_euro,OPcatégorie,"@Change") + SUMIFS(OPequiv_euro,OPcatégorie,"@Achat métaux"),0) -> 0 | M45: =SUMIFS(OPequiv_euro,OPdevise,M$30,OPcatégorie,"@Change")+SUMIFS(OPequiv_euro,OPdevise,M$30,OPcatégorie,"@Achat métaux") -> -2458.08
J46: Total € | L46: =L43+L44+L45 -> 0 | M46: =M43+M44+M45 -> -2458.08
J47: INCONNUS (Comptes, Devises) | K47: =IF(L47=0,"✓","✗") -> ✓ | L47: =SUMPRODUCT((COUNTIF(AVRintitulé,OPcompte)=0)*(OPcompte<>""))+SUMPRODUCT(ISNUMBER(OPdate)*(OPcompte="")*(LEFT(OPcatégorie,1)<>"#"))+SUMPRODUCT((COUNTIF(COTcode,OPdevise)=0)*(OPdevise<>""))+SUMPRODUCT(ISNUMBER(OPdate)*(OPdevise="")*(LEFT(OPcatégorie,1)<>"#")) -> 0
J48: FORMULES | K48: =IF(L48>0,"✗","✓") -> ✓ | L48: =SUM(L49:L50) -> 0
J49: Avoirs | L49: =IF(Avoirs!L1="✗",1,0) -> 0
J50: Plus_value | L50: =IF(Plus_value!B3="✗",1,0) -> 0
J51: ⚓
...

Sheet Cotations
A1: =Contrôles!$K$52 -> ✓ | F1: =année_courante -> 2026
A2: Devise / unité | B2: Nature | C2: Famille | D2: Décimales | E2: Code | F2: Cours en Euro | G2: Date | H2: Cours de l’Euro
A3: ⚓
A4: Euro | B4: primaire | C4: fiat | D4: 2 | E4: EUR | F4: 1
A5: Gramme d'or Spot | B5: primaire | C5: metal | D5: 2 | E5: XAU | F5: 144.12 | G5: 08/05/2026 | H5: =1/F5 -> 0.0069386622
A6: Gramme d'or Premium (pièces) | B6: dérivée | C6: metal | D6: 5 | E6: OrPr | F6: =F$5*1.043 -> 150.31716 | H6: =1/F6 -> 0.0066526004
A7: Bitcoin | B7: primaire | C7: crypto | D7: 2 | E7: BTC | F7: 61009 | G7: 08/05/2026 | H7: =1/F7 -> 1.6391024e-05
A8: Satoshi (1 / 100 000 000 Bitcoin) | B8: dérivée | C8: crypto | D8: 0 | E8: SAT | F8: =F$7/100000000 -> 0.00061009 | H8: =1/F8 -> 1639.1024
A9: Monero | B9: primaire | C9: crypto | D9: 5 | E9: XMR | F9: 305.02 | G9: 08/05/2026 | H9: =1/F9 -> 0.0032784735
A10: Dollar US | B10: primaire | C10: fiat | D10: 2 | E10: USD | F10: 0.8635 | G10: 08/05/2026 | H10: =1/F10 -> 1.1580776
A11: Dollar Singapour | B11: primaire | C11: fiat | D11: 2 | E11: SGD | F11: 0.6776 | G11: 08/05/2026 | H11: =1/F11 -> 1.4757969
A12: ⚓
A13: Alarme cotations | B13: =IF(SUMPRODUCT((COUNTIF(COTcode,PVLdevise)=0)*(PVLdevise<>""))+SUMPRODUCT((COUNTIF(COTcode,AVRdevise)=0)*(AVRdevise<>""))+IFERROR(SUMPRODUCT((COTcode<>"")*(COTcours="")),1)>0,"⚠","✓") -> ✓
