Workbook

Sheet Patrimoine
B2: =Contrôles!N$48 | C2: Patrimoine et répartition
B3: =année_courante | C3: Avoirs | D3: Valeur | F3: ="dont Plus value latente depuis " & YEAR(Plus_value!G3)
B4: TOTAL | C4: =COUNTA(AVRintitulé) | D4: =Avoirs!L2 | G4: =Plus_value!E3 | H4: =Plus_value!F51
B5: par type / compte
B6: Biens matériels | C6: =COUNTIF(AVRtype,$B6) | D6: =SUMIF(AVRtype,$B6,AVRmontant_solde_euro) | E6: =D6/D$13
B7: Portefeuilles | C7: =COUNTIF(AVRtype,$B7) | D7: =SUMIF(AVRtype,$B7,AVRmontant_solde_euro) | E7: =D7/D$13
B8: Créances | C8: =COUNTIF(AVRtype,$B8) | D8: =SUMIF(AVRtype,$B8,AVRmontant_solde_euro) | E8: =D8/D$13
B9: Devises étrangères | C9: =COUNTIF(AVRtype,$B9) | D9: =SUMIF(AVRtype,$B9,AVRmontant_solde_euro) | E9: =D9/D$13
B10: Crypto monnaies | C10: =COUNTIF(AVRtype,$B10) | D10: =SUMIF(AVRtype,$B10,AVRmontant_solde_euro) | E10: =D10/D$13
B11: Euros | C11: =COUNTIF(AVRtype,$B11) | D11: =SUMIF(AVRtype,$B11,AVRmontant_solde_euro) | E11: =D11/D$13
B12: Dettes | C12: =COUNTIF(AVRtype,$B12) | D12: =SUMIF(AVRtype,$B12,AVRmontant_solde_euro) | E12: =D12/D$13
B13: TOTAL | C13: =SUM(C6:C12) | D13: =ROUND(SUM(D6:D12),2)
B14: par sous-type
B15: Foncier | C15: =COUNTIF(AVRsous_type,$B15) | D15: =SUMIF(AVRsous_type,B15,AVRmontant_solde_euro) | E15: =D15/D$24
B16: Titres | C16: =COUNTIF(AVRsous_type,$B16) | D16: =SUMIF(AVRsous_type,B16,AVRmontant_solde_euro) | E16: =D16/D$24
B17: Mobilier | C17: =COUNTIF(AVRsous_type,$B17) | D17: =SUMIF(AVRsous_type,B17,AVRmontant_solde_euro) | E17: =D17/D$24
B18: Euro | C18: =COUNTIF(AVRsous_type,$B18) | D18: =SUMIF(AVRsous_type,B18,AVRmontant_solde_euro) | E18: =D18/D$24
E19: =D19/D$24
B20: Bitcoin | C20: =COUNTIF(AVRsous_type,$B20) | D20: =SUMIF(AVRsous_type,$B20,AVRmontant_solde_euro) | E20: =D20/D$24
B21: Dollar Singapour | C21: =COUNTIF(AVRsous_type,$B21) | D21: =SUMIF(AVRsous_type,$B21,AVRmontant_solde_euro) | E21: =D21/D$24
B22: Dollar US | C22: =COUNTIF(AVRsous_type,$B22) | D22: =SUMIF(AVRsous_type,$B22,AVRmontant_solde_euro) | E22: =D22/D$24
B23: Monero | C23: =COUNTIF(AVRsous_type,$B23) | D23: =SUMIF(AVRsous_type,$B23,AVRmontant_solde_euro) | E23: =D23/D$24
B24: TOTAL | C24: =SUM(C15:C23) | D24: =ROUND(SUM(D15:D23),2)
B25: par domiciliation
E26: =D26/D$41
B27: Amazon | C27: =COUNTIF(AVRdomiciliation,$B27) | D27: =SUMIF(AVRdomiciliation,$B27,AVRmontant_solde_euro) | E27: =D27/D$41
B28: Auto | C28: =COUNTIF(AVRdomiciliation,$B28) | D28: =SUMIF(AVRdomiciliation,$B28,AVRmontant_solde_euro) | E28: =D28/D$41
B29: Blockchain | C29: =COUNTIF(AVRdomiciliation,$B29) | D29: =SUMIF(AVRdomiciliation,$B29,AVRmontant_solde_euro) | E29: =D29/D$41
B30: BoursoBank | C30: =COUNTIF(AVRdomiciliation,$B30) | D30: =SUMIF(AVRdomiciliation,$B30,AVRmontant_solde_euro) | E30: =D30/D$41
B31: Coffre | C31: =COUNTIF(AVRdomiciliation,$B31) | D31: =SUMIF(AVRdomiciliation,$B31,AVRmontant_solde_euro) | E31: =D31/D$41
B32: DEGIRO | C32: =COUNTIF(AVRdomiciliation,$B32) | D32: =SUMIF(AVRdomiciliation,$B32,AVRmontant_solde_euro) | E32: =D32/D$41
B33: Francine | C33: =COUNTIF(AVRdomiciliation,$B33) | D33: =SUMIF(AVRdomiciliation,$B33,AVRmontant_solde_euro) | E33: =D33/D$41
B34: Kraken | C34: =COUNTIF(AVRdomiciliation,$B34) | D34: =SUMIF(AVRdomiciliation,$B34,AVRmontant_solde_euro) | E34: =D34/D$41
B35: Maison | C35: =COUNTIF(AVRdomiciliation,$B35) | D35: =SUMIF(AVRdomiciliation,$B35,AVRmontant_solde_euro) | E35: =D35/D$41
B36: Natixis | C36: =COUNTIF(AVRdomiciliation,$B36) | D36: =SUMIF(AVRdomiciliation,$B36,AVRmontant_solde_euro) | E36: =D36/D$41
B37: Paypal | C37: =COUNTIF(AVRdomiciliation,$B37) | D37: =SUMIF(AVRdomiciliation,$B37,AVRmontant_solde_euro) | E37: =D37/D$41
B38: Société Générale | C38: =COUNTIF(AVRdomiciliation,$B38) | D38: =SUMIF(AVRdomiciliation,$B38,AVRmontant_solde_euro) | E38: =D38/D$41
... B40: eToro | C40: =COUNTIF(AVRdomiciliation,$B40) | D40: =SUMIF(AVRdomiciliation,$B40,AVRmontant_solde_euro) | E40: =D40/D$41
B41: TOTAL | C41: =SUM(C26:C40) | D41: =ROUND(SUM(D26:D40),2)
B42: par titulaire
...

Sheet Avoirs
A1: 2026 | B1: Inventaire des avoirs bancaires, créances, espèces, valeurs précieuses, mobiliers, fonciers. | L1: 142580.98 | M1: donnée
A2: =Contrôles!N$48 | I2: Antériorité | J2: Antériorité | K2: Solde courant | L2: =L32 | M2: formule
A3: Intitulé | B3: Type | C3: Domiciliation | D3: Sous-type | E3: Devise | F3: Titulaire | G3: Propriété | H3: Date | I3: Montant | J3: Date | K3: Montant devise | L3: Montant €
A5: Assurance vie Alice | B5: Portefeuilles | C5: Société Générale | D5: Titres | E5: EUR | F5: Alice | G5: non | H5: 40664 | I5: 210000 | J5: =SUMIFS(PVLdate,PVLcompte,$A5,PVLtitre,Retenu) | K5: =SUMIFS(PVLmontant,PVLcompte,$A5,PVLtitre,Retenu) | L5: =K5
A6: PEE Alice | B6: Portefeuilles | C6: Natixis | D6: Titres | E6: EUR | F6: Alice | G6: non | J6: =SUMIFS(PVLdate,PVLcompte,$A6,PVLtitre,Retenu) | K6: =SUMIFS(PVLmontant,PVLcompte,$A6,PVLtitre,Retenu) | L6: =K6
A7: Portefeuille BB Titres | B7: Portefeuilles | C7: BoursoBank | D7: Titres | E7: EUR | F7: Barnabé | G7: non | H7: 45485 | J7: =SUMIFS(PVLdate,PVLcompte,$A7,PVLtitre,Retenu) | K7: =SUMIFS(PVLmontant,PVLcompte,$A7,PVLtitre,Retenu) | L7: =K7
A8: Portefeuille DEGIRO Titres | B8: Portefeuilles | C8: DEGIRO | D8: Titres | E8: EUR | F8: Barnabé | G8: non | H8: 45617 | J8: =SUMIFS(PVLdate,PVLcompte,$A8,PVLtitre,Retenu) | K8: =SUMIFS(PVLmontant,PVLcompte,$A8,PVLtitre,Retenu) | L8: =K8
A9: Portefeuille eToro USD Titres | B9: Portefeuilles | C9: eToro | D9: Titres | E9: USD | F9: Barnabé | G9: non | H9: 45622 | J9: =SUMIFS(PVLdate,PVLcompte,$A9,PVLtitre,Retenu) | K9: =SUMIFS(PVLmontant,PVLcompte,$A9,PVLtitre,Retenu) | L9: =K9*cours_USD
A10: Compte Amazon | B10: Euros | C10: Amazon | D10: Euro | E10: EUR | F10: Barnabé | G10: non | J10: =_xlfn.MAXIFS(OPdate,OPcompte,$A10,OPdevise,$E10,OPcatégorie,Solde) | K10: =SUMIFS(OPmontant,OPcompte,$A10,OPdevise,$E10,OPcatégorie,Solde,OPdate,$J10) | L10: =K10
A11: Compte chèque BB | B11: Euros | C11: BoursoBank | D11: Euro | E11: EUR | F11: Barnabé | G11: non | H11: 45292 | J11: =_xlfn.MAXIFS(OPdate,OPcompte,$A11,OPdevise,$E11,OPcatégorie,Solde) | K11: =SUMIFS(OPmontant,OPcompte,$A11,OPdevise,$E11,OPcatégorie,Solde,OPdate,$J11) | L11: =K11
A12: Compte chèque commun | B12: Euros | C12: Société Générale | D12: Euro | E12: EUR | F12: Commun | G12: non | H12: 28126 | J12: =_xlfn.MAXIFS(OPdate,OPcompte,$A12,OPdevise,$E12,OPcatégorie,Solde) | K12: =SUMIFS(OPmontant,OPcompte,$A12,OPdevise,$E12,OPcatégorie,Solde,OPdate,$J12) | L12: =K12
A13: Espèces | B13: Euros | C13: Maison | D13: Euro | E13: EUR | F13: Commun | G13: oui | J13: =_xlfn.MAXIFS(OPdate,OPcompte,$A13,OPdevise,$E13,OPcatégorie,Solde) | K13: =SUMIFS(OPmontant,OPcompte,$A13,OPdevise,$E13,OPcatégorie,Solde,OPdate,$J13) | L13: =K13
A14: Livret A Barnabé | B14: Euros | C14: Société Générale | D14: Euro | E14: EUR | F14: Barnabé | G14: non | J14: =_xlfn.MAXIFS(OPdate,OPcompte,$A14,OPdevise,$E14,OPcatégorie,Solde) | K14: =SUMIFS(OPmontant,OPcompte,$A14,OPdevise,$E14,OPcatégorie,Solde,OPdate,$J14) | L14: =K14
A15: Compte Paypal | B15: Euros | C15: Paypal | D15: Euro | E15: EUR | F15: Barnabé | G15: non | J15: =_xlfn.MAXIFS(OPdate,OPcompte,$A15,OPdevise,$E15,OPcatégorie,Solde) | K15: =SUMIFS(OPmontant,OPcompte,$A15,OPdevise,$E15,OPcatégorie,Solde,OPdate,$J15) | L15: =K15
A16: Compte Wise EUR | B16: Euros | C16: Wise | D16: Euro | E16: EUR | F16: Barnabé | G16: non | H16: 45627 | J16: =_xlfn.MAXIFS(OPdate,OPcompte,$A16,OPdevise,$E16,OPcatégorie,Solde) | K16: =SUMIFS(OPmontant,OPcompte,$A16,OPdevise,$E16,OPcatégorie,Solde,OPdate,$J16) | L16: =K16
A17: Portefeuille DEGIRO Réserve | B17: Euros | C17: DEGIRO | D17: Euro | E17: EUR | F17: Barnabé | G17: non | J17: =_xlfn.MAXIFS(OPdate,OPcompte,$A17,OPdevise,$E17,OPcatégorie,Solde) | K17: =SUMIFS(OPmontant,OPcompte,$A17,OPdevise,$E17,OPcatégorie,Solde,OPdate,$J17) | L17: =K17
A18: Portefeuille BB Réserve | B18: Euros | C18: BoursoBank | D18: Euro | E18: EUR | F18: Barnabé | G18: non | J18: =_xlfn.MAXIFS(OPdate,OPcompte,$A18,OPdevise,$E18,OPcatégorie,Solde) | K18: =SUMIFS(OPmontant,OPcompte,$A18,OPdevise,$E18,OPcatégorie,Solde,OPdate,$J18) | L18: =K18
A19: Compte Wise USD | B19: Devises étrangères | C19: Wise | D19: Dollar US | E19: USD | F19: Barnabé | G19: non | H19: 45653 | J19: =_xlfn.MAXIFS(OPdate,OPcompte,$A19,OPdevise,$E19,OPcatégorie,Solde) | K19: =SUMIFS(OPmontant,OPcompte,$A19,OPdevise,$E19,OPcatégorie,Solde,OPdate,$J19) | L19: =K19*cours_USD
A20: Compte Wise SGD | B20: Devises étrangères | C20: Wise | D20: Dollar Singapour | E20: SGD | F20: Barnabé | G20: non | H20: 45631 | J20: =_xlfn.MAXIFS(OPdate,OPcompte,$A20,OPdevise,$E20,OPcatégorie,Solde) | K20: =SUMIFS(OPmontant,OPcompte,$A20,OPdevise,$E20,OPcatégorie,Solde,OPdate,$J20) | L20: =K20*cours_SGD
A21: Portefeuille eToro USD Réserve | B21: Devises étrangères | C21: eToro | D21: Dollar US | E21: USD | F21: Barnabé | G21: non | J21: =_xlfn.MAXIFS(OPdate,OPcompte,$A21,OPdevise,$E21,OPcatégorie,Solde) | K21: =SUMIFS(OPmontant,OPcompte,$A21,OPdevise,$E21,OPcatégorie,Solde,OPdate,$J21) | L21: =K21*cours_USD
A22: Créance Francine | B22: Créances | C22: Francine | D22: Euro | E22: EUR | F22: Commun | G22: non | H22: 42873 | I22: 156270 | J22: =_xlfn.MAXIFS(OPdate,OPcompte,$A22,OPdevise,$E22,OPcatégorie,Solde) | K22: =SUMIFS(OPmontant,OPcompte,$A22,OPdevise,$E22,OPcatégorie,Solde,OPdate,$J22) | L22: =K22
A23: BlueWallet BTC | B23: Crypto monnaies | C23: Blockchain | D23: Bitcoin | E23: SAT | F23: Commun | G23: oui | H23: 44967 | J23: =_xlfn.MAXIFS(OPdate,OPcompte,$A23,OPdevise,$E23,OPcatégorie,Solde) | K23: =SUMIFS(OPmontant,OPcompte,$A23,OPdevise,$E23,OPcatégorie,Solde,OPdate,$J23) | L23: =K23*cours_SAT
A24: Phoenix Lightning BTC | B24: Crypto monnaies | C24: Blockchain | D24: Bitcoin | E24: SAT | F24: Commun | G24: oui | H24: 44967 | J24: =_xlfn.MAXIFS(OPdate,OPcompte,$A24,OPdevise,$E24,OPcatégorie,Solde) | K24: =SUMIFS(OPmontant,OPcompte,$A24,OPdevise,$E24,OPcatégorie,Solde,OPdate,$J24) | L24: =K24*cours_SAT
A25: Compte Kraken BTC | B25: Crypto monnaies | C25: Kraken | D25: Bitcoin | E25: SAT | F25: Commun | G25: non | H25: 45855 | J25: =_xlfn.MAXIFS(OPdate,OPcompte,$A25,OPdevise,$E25,OPcatégorie,Solde) | K25: =SUMIFS(OPmontant,OPcompte,$A25,OPdevise,$E25,OPcatégorie,Solde,OPdate,$J25) | L25: =K25*cours_SAT
A26: Cake Wallet XMR | B26: Crypto monnaies | C26: Blockchain | D26: Monero | E26: XMR | F26: Commun | G26: oui | H26: 44999 | J26: =_xlfn.MAXIFS(OPdate,OPcompte,$A26,OPdevise,$E26,OPcatégorie,Solde) | K26: =SUMIFS(OPmontant,OPcompte,$A26,OPdevise,$E26,OPcatégorie,Solde,OPdate,$J26) | L26: =K26*cours_XMR
A27: Pièces or | B27: Biens matériels | C27: Coffre | D27: Mobilier | E27: OrPr | F27: Commun | G27: oui | H27: 45048 | J27: =_xlfn.MAXIFS(OPdate,OPcompte,$A27,OPdevise,$E27,OPcatégorie,Solde) | K27: =SUMIFS(OPmontant,OPcompte,$A27,OPdevise,$E27,OPcatégorie,Solde,OPdate,$J27) | L27: =K27*cours_OrPr
A28: Maison | B28: Biens matériels | C28: Maison | D28: Foncier | F28: Commun | G28: oui | H28: 43750 | I28: 200000 | K28: 100000 | L28: =K28
A29: Auto | B29: Biens matériels | C29: Auto | D29: Mobilier | F29: Commun | G29: oui | H29: 37773 | I29: 30000 | K29: 9000 | L29: =K29
A30: Mobilier maison | B30: Biens matériels | C30: Maison | D30: Mobilier | F30: Commun | G30: oui | K30: 15000 | L30: =K30
A32: Total | L32: =ROUND(SUM(L4:L31),2)

Sheet Budget
A1: =Contrôles!N$48 | C1: =C$2-365
C2: =TODAY()
A3: Dépenses et revenus | B3: Type | C3: Année glissante
A5: Maison | B5: Fixe | C5: =SUMIF(Q20:Q34,A5,P20:P34)
A6: Santé | B6: Fixe | C6: =SUMIF(Q20:Q34,A6,P20:P34)
A7: Loisirs et restaurant | B7: Fixe | C7: =SUMIF(Q20:Q34,A7,P20:P34)
A8: Divers | B8: Fixe | C8: =SUMIF(Q20:Q34,A8,P20:P34)
A9: Produits financiers | B9: Fixe | C9: =SUMIF(Q20:Q34,A9,P20:P34)
A11: Total = épargne | C11: =SUM(C5:C9)
A12: Epargne fixe | C12: =SUMIF($B5:$B9,"Fixe",C5:C9)
A13: Epargne fixe / mois | C13: =C$12/12
A14: Écart avec tableau Affectation | C14: =C$11-P$39
E16: CATÉGORIES
E17: Catégories d’opérations de débit et crédit sur année glissante | F17: EUR | G17: XAU | H17: BTC | I17: USD | J17: SGD | K17: OrPr | L17: SAT | M17: XMR | N17: Équivalent € au cours du jour | O17: Affectation % | P17: Affectation | Q17: Dépenses et revenus
E18: START | F18: 1 | G18: =SUMIF(Cotations!$C$3:$C$4,G$17,Cotations!$D$3:$D$4) | H18: =SUMIF(Cotations!$C$3:$C$10,H$17,Cotations!$D$3:$D$10) | I18: =SUMIF(Cotations!$C$3:$C$10,I$17,Cotations!$D$3:$D$10) | J18: =SUMIF(Cotations!$C$3:$C$10,J$17,Cotations!$D$3:$D$10) | K18: =SUMIF(Cotations!$C$3:$C$10,K$17,Cotations!$D$3:$D$10) | L18: =SUMIF(Cotations!$C$3:$C$10,L$17,Cotations!$D$3:$D$10) | M18: =SUMIF(Cotations!$C$3:$C$10,M$17,Cotations!$D$3:$D$10)
E20: Change | F20: =SUMIFS(OPmontant,OPdevise,F$17,OPcatégorie,$E20,OPdate,">"&$C$2-365) | G20: =SUMIFS(OPmontant,OPdevise,G$17,OPcatégorie,$E20,OPdate,">"&$C$2-365) | H20: =SUMIFS(OPmontant,OPdevise,H$17,OPcatégorie,$E20,OPdate,">"&$C$2-365) | I20: =SUMIFS(OPmontant,OPdevise,I$17,OPcatégorie,$E20,OPdate,">"&$C$2-365) | J20: =SUMIFS(OPmontant,OPdevise,J$17,OPcatégorie,$E20,OPdate,">"&$C$2-365) | K20: =SUMIFS(OPmontant,OPdevise,K$17,OPcatégorie,$E20,OPdate,">"&$C$2-365) | L20: =SUMIFS(OPmontant,OPdevise,L$17,OPcatégorie,$E20,OPdate,">"&$C$2-365) | M20: =SUMIFS(OPmontant,OPdevise,M$17,OPcatégorie,$E20,OPdate,">"&$C$2-365) | Q20: Divers
E21: Achat métaux | F21: =SUMIFS(OPmontant,OPdevise,F$17,OPcatégorie,$E21,OPdate,">"&$C$2-365) | G21: =SUMIFS(OPmontant,OPdevise,G$17,OPcatégorie,$E21,OPdate,">"&$C$2-365) | H21: =SUMIFS(OPmontant,OPdevise,H$17,OPcatégorie,$E21,OPdate,">"&$C$2-365) | I21: =SUMIFS(OPmontant,OPdevise,I$17,OPcatégorie,$E21,OPdate,">"&$C$2-365) | J21: =SUMIFS(OPmontant,OPdevise,J$17,OPcatégorie,$E21,OPdate,">"&$C$2-365) | K21: =SUMIFS(OPmontant,OPdevise,K$17,OPcatégorie,$E21,OPdate,">"&$C$2-365) | L21: =SUMIFS(OPmontant,OPdevise,L$17,OPcatégorie,$E21,OPdate,">"&$C$2-365) | M21: =SUMIFS(OPmontant,OPdevise,M$17,OPcatégorie,$E21,OPdate,">"&$C$2-365) | Q21: Divers
E22: Virement | F22: =SUMIFS(OPmontant,OPdevise,F$17,OPcatégorie,$E22,OPdate,">"&$C$2-365) | G22: =SUMIFS(OPmontant,OPdevise,G$17,OPcatégorie,$E22,OPdate,">"&$C$2-365) | H22: =SUMIFS(OPmontant,OPdevise,H$17,OPcatégorie,$E22,OPdate,">"&$C$2-365) | I22: =SUMIFS(OPmontant,OPdevise,I$17,OPcatégorie,$E22,OPdate,">"&$C$2-365) | J22: =SUMIFS(OPmontant,OPdevise,J$17,OPcatégorie,$E22,OPdate,">"&$C$2-365) | K22: =SUMIFS(OPmontant,OPdevise,K$17,OPcatégorie,$E22,OPdate,">"&$C$2-365) | L22: =SUMIFS(OPmontant,OPdevise,L$17,OPcatégorie,$E22,OPdate,">"&$C$2-365) | M22: =SUMIFS(OPmontant,OPdevise,M$17,OPcatégorie,$E22,OPdate,">"&$C$2-365) | Q22: Divers
E23: Achat titres | F23: =SUMIFS(OPmontant,OPdevise,F$17,OPcatégorie,$E23,OPdate,">"&$C$2-365) | G23: =SUMIFS(OPmontant,OPdevise,G$17,OPcatégorie,$E23,OPdate,">"&$C$2-365) | H23: =SUMIFS(OPmontant,OPdevise,H$17,OPcatégorie,$E23,OPdate,">"&$C$2-365) | I23: =SUMIFS(OPmontant,OPdevise,I$17,OPcatégorie,$E23,OPdate,">"&$C$2-365) | J23: =SUMIFS(OPmontant,OPdevise,J$17,OPcatégorie,$E23,OPdate,">"&$C$2-365) | K23: =SUMIFS(OPmontant,OPdevise,K$17,OPcatégorie,$E23,OPdate,">"&$C$2-365) | L23: =SUMIFS(OPmontant,OPdevise,L$17,OPcatégorie,$E23,OPdate,">"&$C$2-365) | M23: =SUMIFS(OPmontant,OPdevise,M$17,OPcatégorie,$E23,OPdate,">"&$C$2-365) | Q23: Divers
E24: Vente titres | F24: =SUMIFS(OPmontant,OPdevise,F$17,OPcatégorie,$E24,OPdate,">"&$C$2-365) | G24: =SUMIFS(OPmontant,OPdevise,G$17,OPcatégorie,$E24,OPdate,">"&$C$2-365) | H24: =SUMIFS(OPmontant,OPdevise,H$17,OPcatégorie,$E24,OPdate,">"&$C$2-365) | I24: =SUMIFS(OPmontant,OPdevise,I$17,OPcatégorie,$E24,OPdate,">"&$C$2-365) | J24: =SUMIFS(OPmontant,OPdevise,J$17,OPcatégorie,$E24,OPdate,">"&$C$2-365) | K24: =SUMIFS(OPmontant,OPdevise,K$17,OPcatégorie,$E24,OPdate,">"&$C$2-365) | L24: =SUMIFS(OPmontant,OPdevise,L$17,OPcatégorie,$E24,OPdate,">"&$C$2-365) | M24: =SUMIFS(OPmontant,OPdevise,M$17,OPcatégorie,$E24,OPdate,">"&$C$2-365) | Q24: Divers
E25: Arbitrage titres | F25: =SUMIFS(OPmontant,OPdevise,F$17,OPcatégorie,$E25,OPdate,">"&$C$2-365) | G25: =SUMIFS(OPmontant,OPdevise,G$17,OPcatégorie,$E25,OPdate,">"&$C$2-365) | H25: =SUMIFS(OPmontant,OPdevise,H$17,OPcatégorie,$E25,OPdate,">"&$C$2-365) | I25: =SUMIFS(OPmontant,OPdevise,I$17,OPcatégorie,$E25,OPdate,">"&$C$2-365) | J25: =SUMIFS(OPmontant,OPdevise,J$17,OPcatégorie,$E25,OPdate,">"&$C$2-365) | K25: =SUMIFS(OPmontant,OPdevise,K$17,OPcatégorie,$E25,OPdate,">"&$C$2-365) | L25: =SUMIFS(OPmontant,OPdevise,L$17,OPcatégorie,$E25,OPdate,">"&$C$2-365) | M25: =SUMIFS(OPmontant,OPdevise,M$17,OPcatégorie,$E25,OPdate,">"&$C$2-365) | Q25: Divers
E26: Ajustement | F26: =SUMIFS(OPmontant,OPdevise,F$17,OPcatégorie,$E26,OPdate,">"&$C$2-365) | G26: =SUMIFS(OPmontant,OPdevise,G$17,OPcatégorie,$E26,OPdate,">"&$C$2-365) | H26: =SUMIFS(OPmontant,OPdevise,H$17,OPcatégorie,$E26,OPdate,">"&$C$2-365) | I26: =SUMIFS(OPmontant,OPdevise,I$17,OPcatégorie,$E26,OPdate,">"&$C$2-365) | J26: =SUMIFS(OPmontant,OPdevise,J$17,OPcatégorie,$E26,OPdate,">"&$C$2-365) | K26: =SUMIFS(OPmontant,OPdevise,K$17,OPcatégorie,$E26,OPdate,">"&$C$2-365) | L26: =SUMIFS(OPmontant,OPdevise,L$17,OPcatégorie,$E26,OPdate,">"&$C$2-365) | M26: =SUMIFS(OPmontant,OPdevise,M$17,OPcatégorie,$E26,OPdate,">"&$C$2-365) | N26: =SUMPRODUCT(F26:M26,F$18:M$18) | O26: 1 | P26: =N26*O26 | Q26: Divers
E27: Coupon | F27: =SUMIFS(OPmontant,OPdevise,F$17,OPcatégorie,$E27,OPdate,">"&$C$2-365) | G27: =SUMIFS(OPmontant,OPdevise,G$17,OPcatégorie,$E27,OPdate,">"&$C$2-365) | H27: =SUMIFS(OPmontant,OPdevise,H$17,OPcatégorie,$E27,OPdate,">"&$C$2-365) | I27: =SUMIFS(OPmontant,OPdevise,I$17,OPcatégorie,$E27,OPdate,">"&$C$2-365) | J27: =SUMIFS(OPmontant,OPdevise,J$17,OPcatégorie,$E27,OPdate,">"&$C$2-365) | K27: =SUMIFS(OPmontant,OPdevise,K$17,OPcatégorie,$E27,OPdate,">"&$C$2-365) | L27: =SUMIFS(OPmontant,OPdevise,L$17,OPcatégorie,$E27,OPdate,">"&$C$2-365) | M27: =SUMIFS(OPmontant,OPdevise,M$17,OPcatégorie,$E27,OPdate,">"&$C$2-365) | N27: =SUMPRODUCT(F27:M27,F$18:M$18) | O27: 1 | P27: =N27*O27 | Q27: Produits financiers
E28: Frais bancaires | F28: =SUMIFS(OPmontant,OPdevise,F$17,OPcatégorie,$E28,OPdate,">"&$C$2-365) | G28: =SUMIFS(OPmontant,OPdevise,G$17,OPcatégorie,$E28,OPdate,">"&$C$2-365) | H28: =SUMIFS(OPmontant,OPdevise,H$17,OPcatégorie,$E28,OPdate,">"&$C$2-365) | I28: =SUMIFS(OPmontant,OPdevise,I$17,OPcatégorie,$E28,OPdate,">"&$C$2-365) | J28: =SUMIFS(OPmontant,OPdevise,J$17,OPcatégorie,$E28,OPdate,">"&$C$2-365) | K28: =SUMIFS(OPmontant,OPdevise,K$17,OPcatégorie,$E28,OPdate,">"&$C$2-365) | L28: =SUMIFS(OPmontant,OPdevise,L$17,OPcatégorie,$E28,OPdate,">"&$C$2-365) | M28: =SUMIFS(OPmontant,OPdevise,M$17,OPcatégorie,$E28,OPdate,">"&$C$2-365) | N28: =SUMPRODUCT(F28:M28,F$18:M$18) | O28: 1 | P28: =N28*O28 | Q28: Produits financiers
E29: Intérêts | F29: =SUMIFS(OPmontant,OPdevise,F$17,OPcatégorie,$E29,OPdate,">"&$C$2-365) | G29: =SUMIFS(OPmontant,OPdevise,G$17,OPcatégorie,$E29,OPdate,">"&$C$2-365) | H29: =SUMIFS(OPmontant,OPdevise,H$17,OPcatégorie,$E29,OPdate,">"&$C$2-365) | I29: =SUMIFS(OPmontant,OPdevise,I$17,OPcatégorie,$E29,OPdate,">"&$C$2-365) | J29: =SUMIFS(OPmontant,OPdevise,J$17,OPcatégorie,$E29,OPdate,">"&$C$2-365) | K29: =SUMIFS(OPmontant,OPdevise,K$17,OPcatégorie,$E29,OPdate,">"&$C$2-365) | L29: =SUMIFS(OPmontant,OPdevise,L$17,OPcatégorie,$E29,OPdate,">"&$C$2-365) | M29: =SUMIFS(OPmontant,OPdevise,M$17,OPcatégorie,$E29,OPdate,">"&$C$2-365) | N29: =SUMPRODUCT(F29:M29,F$18:M$18) | O29: 1 | P29: =N29*O29 | Q29: Produits financiers
E30: Loisirs | F30: =SUMIFS(OPmontant,OPdevise,F$17,OPcatégorie,$E30,OPdate,">"&$C$2-365) | G30: =SUMIFS(OPmontant,OPdevise,G$17,OPcatégorie,$E30,OPdate,">"&$C$2-365) | H30: =SUMIFS(OPmontant,OPdevise,H$17,OPcatégorie,$E30,OPdate,">"&$C$2-365) | I30: =SUMIFS(OPmontant,OPdevise,I$17,OPcatégorie,$E30,OPdate,">"&$C$2-365) | J30: =SUMIFS(OPmontant,OPdevise,J$17,OPcatégorie,$E30,OPdate,">"&$C$2-365) | K30: =SUMIFS(OPmontant,OPdevise,K$17,OPcatégorie,$E30,OPdate,">"&$C$2-365) | L30: =SUMIFS(OPmontant,OPdevise,L$17,OPcatégorie,$E30,OPdate,">"&$C$2-365) | M30: =SUMIFS(OPmontant,OPdevise,M$17,OPcatégorie,$E30,OPdate,">"&$C$2-365) | N30: =SUMPRODUCT(F30:M30,F$18:M$18) | O30: 1 | P30: =N30*O30 | Q30: Loisirs et restaurant
E31: Maison | F31: =SUMIFS(OPmontant,OPdevise,F$17,OPcatégorie,$E31,OPdate,">"&$C$2-365) | G31: =SUMIFS(OPmontant,OPdevise,G$17,OPcatégorie,$E31,OPdate,">"&$C$2-365) | H31: =SUMIFS(OPmontant,OPdevise,H$17,OPcatégorie,$E31,OPdate,">"&$C$2-365) | I31: =SUMIFS(OPmontant,OPdevise,I$17,OPcatégorie,$E31,OPdate,">"&$C$2-365) | J31: =SUMIFS(OPmontant,OPdevise,J$17,OPcatégorie,$E31,OPdate,">"&$C$2-365) | K31: =SUMIFS(OPmontant,OPdevise,K$17,OPcatégorie,$E31,OPdate,">"&$C$2-365) | L31: =SUMIFS(OPmontant,OPdevise,L$17,OPcatégorie,$E31,OPdate,">"&$C$2-365) | M31: =SUMIFS(OPmontant,OPdevise,M$17,OPcatégorie,$E31,OPdate,">"&$C$2-365) | N31: =SUMPRODUCT(F31:M31,F$18:M$18) | O31: 1 | P31: =N31*O31 | Q31: Maison
E32: Restaurant | F32: =SUMIFS(OPmontant,OPdevise,F$17,OPcatégorie,$E32,OPdate,">"&$C$2-365) | G32: =SUMIFS(OPmontant,OPdevise,G$17,OPcatégorie,$E32,OPdate,">"&$C$2-365) | H32: =SUMIFS(OPmontant,OPdevise,H$17,OPcatégorie,$E32,OPdate,">"&$C$2-365) | I32: =SUMIFS(OPmontant,OPdevise,I$17,OPcatégorie,$E32,OPdate,">"&$C$2-365) | J32: =SUMIFS(OPmontant,OPdevise,J$17,OPcatégorie,$E32,OPdate,">"&$C$2-365) | K32: =SUMIFS(OPmontant,OPdevise,K$17,OPcatégorie,$E32,OPdate,">"&$C$2-365) | L32: =SUMIFS(OPmontant,OPdevise,L$17,OPcatégorie,$E32,OPdate,">"&$C$2-365) | M32: =SUMIFS(OPmontant,OPdevise,M$17,OPcatégorie,$E32,OPdate,">"&$C$2-365) | N32: =SUMPRODUCT(F32:M32,F$18:M$18) | O32: 1 | P32: =N32*O32 | Q32: Loisirs et restaurant
E33: Santé | F33: =SUMIFS(OPmontant,OPdevise,F$17,OPcatégorie,$E33,OPdate,">"&$C$2-365) | G33: =SUMIFS(OPmontant,OPdevise,G$17,OPcatégorie,$E33,OPdate,">"&$C$2-365) | H33: =SUMIFS(OPmontant,OPdevise,H$17,OPcatégorie,$E33,OPdate,">"&$C$2-365) | I33: =SUMIFS(OPmontant,OPdevise,I$17,OPcatégorie,$E33,OPdate,">"&$C$2-365) | J33: =SUMIFS(OPmontant,OPdevise,J$17,OPcatégorie,$E33,OPdate,">"&$C$2-365) | K33: =SUMIFS(OPmontant,OPdevise,K$17,OPcatégorie,$E33,OPdate,">"&$C$2-365) | L33: =SUMIFS(OPmontant,OPdevise,L$17,OPcatégorie,$E33,OPdate,">"&$C$2-365) | M33: =SUMIFS(OPmontant,OPdevise,M$17,OPcatégorie,$E33,OPdate,">"&$C$2-365) | N33: =SUMPRODUCT(F33:M33,F$18:M$18) | O33: 1 | P33: =N33*O33 | Q33: Santé
E34: - | F34: =SUMIFS(OPmontant,OPdevise,F$17,OPcatégorie,$E34,OPdate,">"&$C$2-365) | N34: =SUMPRODUCT(F34:M34,F$18:M$18) | O34: 1 | P34: =N34*O34 | Q34: Divers
E36: Total | F36: =SUM(F20:F34) | G36: =SUM(G20:G34) | H36: =SUM(H20:H34) | I36: =SUM(I20:I34) | J36: =SUM(J20:J34) | K36: =SUM(K20:K34) | L36: =SUM(L20:L34) | M36: =SUM(M20:M34)
E37: Somme opérations | F37: =SUMIFS(OPmontant,OPdevise,F$17,OPdate,">"&$C$2-365,OPcatégorie,"<>"&Spéciale) | G37: =SUMIFS(OPmontant,OPdevise,G$17,OPdate,">"&$C$2-365,OPcatégorie,"<>"&Spéciale) | H37: =SUMIFS(OPmontant,OPdevise,H$17,OPdate,">"&$C$2-365,OPcatégorie,"<>"&Spéciale) | I37: =SUMIFS(OPmontant,OPdevise,I$17,OPdate,">"&$C$2-365,OPcatégorie,"<>"&Spéciale) | J37: =SUMIFS(OPmontant,OPdevise,J$17,OPdate,">"&$C$2-365,OPcatégorie,"<>"&Spéciale) | K37: =SUMIFS(OPmontant,OPdevise,K$17,OPdate,">"&$C$2-365,OPcatégorie,"<>"&Spéciale) | L37: =SUMIFS(OPmontant,OPdevise,L$17,OPdate,">"&$C$2-365,OPcatégorie,"<>"&Spéciale) | M37: =SUMIFS(OPmontant,OPdevise,M$17,OPdate,">"&$C$2-365,OPcatégorie,"<>"&Spéciale)
E38: Écart | F38: =ROUND(F$36-F$37,2) | G38: =G$36-G$37 | H38: =H$36-H$37 | I38: =I$36-I$37 | J38: =J$36-J$37 | K38: =K$36-K$37 | L38: =L$36-L$37 | M38: =M$36-M$37
E39: Total hors Changes et Virements | F39: =SUM(F26:F34) | G39: =SUM(G26:G34) | H39: =SUM(H26:H34) | I39: =SUM(I26:I34) | J39: =SUM(J26:J34) | K39: =SUM(K26:K34) | L39: =SUM(L26:L34) | M39: =SUM(M26:M34) | N39: =SUM(N26:N34) | P39: =SUM(P26:P34)
E40: Montant Euros | F40: =F$39 | G40: =G$39*G$18 | H40: =H$39*H$18 | I40: =I$39*I$18 | J40: =J$39*J$18 | K40: =K$39*K$18 | L40: =L$39*L$18 | M40: =M$39*M$18 | N40: =SUM(F$40:M$40)

Sheet Plus_value
B1: La plus value latente, PVL, est la différence entre la valorisation au cours du jour (SOLDE) et la somme des opérations passées aux cours d’époque (Montant initial + SIGMA).
B2: =Contrôles!N48 | C2: Le solde retenu d’un portefeuille est le plus récent entre cette feuille (Total) et Opérations (#Solde)
E3: =E51 | G3: =G51
A4: Section | B4: Compte | C4: Ligne | D4: Devise | E4: PVL | F4: PVL % | G4: Date initiale | H4: Montant initial | I4: SIGMA | J4: Date SOLDE | K4: SOLDE
A5: Les portefeuilles
A7: portefeuilles | B7: Assurance vie Alice | C7: Portefeuille
A8: portefeuilles | B8: Assurance vie Alice | C8: Total | D8: EUR | E8: =K8-(H8+I8) | G8: 0 | H8: 0 | I8: 0 | K8: 0
A9: portefeuilles | B9: Assurance vie Alice | C9: #Solde Opérations | D9: EUR | E9: =K9-(H9+I9) | G9: =_xlfn.MINIFS(OPdate,OPcompte,$B9,OPdevise,D9,OPcatégorie,Solde) | H9: =SUMIFS(OPmontant,OPcompte,$B9,OPdevise,$D9,OPdate,$G9,OPcatégorie,Solde) | I9: =I8 | J9: =_xlfn.MAXIFS(OPdate,OPcompte,$B9,OPdevise,$D9,OPcatégorie,Solde) | K9: =SUMIFS(OPmontant,OPcompte,$B9,OPdevise,$D9,OPcatégorie,Solde,OPdate,J9)
A10: portefeuilles | B10: Assurance vie Alice | C10: Retenu | D10: EUR | E10: =K10-(H10+I10) | G10: =G9 | H10: =H9 | I10: =I9 | J10: =IF(J8>J9,J8,J9) | K10: =IF(J8>J9,K8,K9)
A12: portefeuilles | B12: PEE Alice | C12: Portefeuille
A13: portefeuilles | B13: PEE Alice | C13: Total | D13: EUR | E13: =K13-(H13+I13) | G13: 0 | H13: 0 | I13: 0 | K13: 0
A14: portefeuilles | B14: PEE Alice | C14: #Solde Opérations | D14: EUR | E14: =K14-(H14+I14) | G14: =_xlfn.MINIFS(OPdate,OPcompte,$B14,OPdevise,D14,OPcatégorie,Solde) | H14: =SUMIFS(OPmontant,OPcompte,$B14,OPdevise,$D14,OPdate,$G14,OPcatégorie,Solde) | I14: =I13 | J14: =_xlfn.MAXIFS(OPdate,OPcompte,$B14,OPdevise,$D14,OPcatégorie,Solde) | K14: =SUMIFS(OPmontant,OPcompte,$B14,OPdevise,$D14,OPcatégorie,Solde,OPdate,J14)
A15: portefeuilles | B15: PEE Alice | C15: Retenu | D15: EUR | E15: =K15-(H15+I15) | G15: =G14 | H15: =H14 | I15: =I14 | J15: =IF(J13>J14,J13,J14) | K15: =IF(J13>J14,K13,K14)
A17: portefeuilles | B17: Portefeuille BB Titres | C17: Portefeuille
A18: portefeuilles | B18: Portefeuille BB Titres | C18: Total | D18: EUR | E18: =K18-(H18+I18) | G18: 0 | H18: 0 | I18: 0 | K18: 0
A19: portefeuilles | B19: Portefeuille BB Titres | C19: #Solde Opérations | D19: EUR | E19: =K19-(H19+I19) | G19: =_xlfn.MINIFS(OPdate,OPcompte,$B19,OPdevise,D19,OPcatégorie,Solde) | H19: =SUMIFS(OPmontant,OPcompte,$B19,OPdevise,$D19,OPdate,$G19,OPcatégorie,Solde) | I19: =I18 | J19: =_xlfn.MAXIFS(OPdate,OPcompte,$B19,OPdevise,$D19,OPcatégorie,Solde) | K19: =SUMIFS(OPmontant,OPcompte,$B19,OPdevise,$D19,OPcatégorie,Solde,OPdate,J19)
A20: portefeuilles | B20: Portefeuille BB Titres | C20: Retenu | D20: EUR | E20: =K20-(H20+I20) | G20: =G19 | H20: =H19 | I20: =I19 | J20: =IF(J18>J19,J18,J19) | K20: =IF(J18>J19,K18,K19)
A22: portefeuilles | B22: Portefeuille DEGIRO Titres | C22: Portefeuille
A23: portefeuilles | B23: Portefeuille DEGIRO Titres | C23: Total | D23: EUR | E23: =K23-(H23+I23) | G23: 0 | H23: 0 | I23: 0 | K23: 0
A24: portefeuilles | B24: Portefeuille DEGIRO Titres | C24: #Solde Opérations | D24: EUR | E24: =K24-(H24+I24) | G24: =_xlfn.MINIFS(OPdate,OPcompte,$B24,OPdevise,D24,OPcatégorie,Solde) | H24: =SUMIFS(OPmontant,OPcompte,$B24,OPdevise,$D24,OPdate,$G24,OPcatégorie,Solde) | I24: =I23 | J24: =_xlfn.MAXIFS(OPdate,OPcompte,$B24,OPdevise,$D24,OPcatégorie,Solde) | K24: =SUMIFS(OPmontant,OPcompte,$B24,OPdevise,$D24,OPcatégorie,Solde,OPdate,J24)
A25: portefeuilles | B25: Portefeuille DEGIRO Titres | C25: Retenu | D25: EUR | E25: =K25-(H25+I25) | G25: =G24 | H25: =H24 | I25: =I24 | J25: =IF(J23>J24,J23,J24) | K25: =IF(J23>J24,K23,K24)
A27: portefeuilles | B27: Portefeuille eToro USD Titres | C27: Portefeuille
A28: portefeuilles | B28: Portefeuille eToro USD Titres | C28: *AI.PA* | D28: USD | E28: =K28-(H28+I28) | G28: 0 | H28: 10 | I28: =SUMIFS(OPmontant,OPcompte,$B28,OPdevise,$D28,OPcatégorie,"<>"&Spéciale,OPlibellé,$C28,OPdate,">="&$G28) | J28: 46083 | K28: 12.62
A29: portefeuilles | B29: Portefeuille eToro USD Titres | C29: *SPX500* | D29: USD | E29: =K29-(H29+I29) | G29: 45715 | H29: 0 | I29: =SUMIFS(OPmontant,OPcompte,$B29,OPdevise,$D29,OPcatégorie,"<>"&Spéciale,OPlibellé,$C29,OPdate,">="&$G29) | J29: 45924 | K29: 0
A30: portefeuilles | B30: Portefeuille eToro USD Titres | C30: *BTC/USD* | D30: USD | E30: =K30-(H30+I30) | G30: 45924 | H30: 0 | I30: =SUMIFS(OPmontant,OPcompte,$B30,OPdevise,$D30,OPcatégorie,"<>"&Spéciale,OPlibellé,$C30,OPdate,">="&$G30) | J30: 46083 | K30: 586.98
A31: portefeuilles | B31: Portefeuille eToro USD Titres | C31: *COMT* | D31: USD | E31: =K31-(H31+I31) | G31: 46048 | H31: 0 | I31: =SUMIFS(OPmontant,OPcompte,$B31,OPdevise,$D31,OPcatégorie,"<>"&Spéciale,OPlibellé,$C31,OPdate,">="&$G31) | J31: 46083 | K31: 2607.14
A32: portefeuilles | B32: Portefeuille eToro USD Titres | C32: *KWEB* | D32: USD | E32: =K32-(H32+I32) | G32: 45783 | H32: 0 | I32: =SUMIFS(OPmontant,OPcompte,$B32,OPdevise,$D32,OPcatégorie,"<>"&Spéciale,OPlibellé,$C32,OPdate,">="&$G32) | J32: 46083 | K32: 181.99
A33: portefeuilles | B33: Portefeuille eToro USD Titres | C33: Total | D33: USD | E33: =K33-(H33+I33) | G33: =MIN(G28:G32) | H33: =SUM(H28:H32) | I33: =SUM(I28:I32) | J33: =J28 | K33: =SUM(K28:K32)
A34: portefeuilles | B34: Portefeuille eToro USD Titres | C34: #Solde Opérations | D34: USD | E34: =K34-(H34+I34) | G34: =_xlfn.MINIFS(OPdate,OPcompte,$B34,OPdevise,D34,OPcatégorie,Solde) | H34: =SUMIFS(OPmontant,OPcompte,$B34,OPdevise,$D34,OPdate,$G34,OPcatégorie,Solde) | I34: =I33 | J34: =_xlfn.MAXIFS(OPdate,OPcompte,$B34,OPdevise,$D34,OPcatégorie,Solde) | K34: =SUMIFS(OPmontant,OPcompte,$B34,OPdevise,$D34,OPcatégorie,Solde,OPdate,J34)
A35: portefeuilles | B35: Portefeuille eToro USD Titres | C35: Retenu | D35: USD | E35: =K35-(H35+I35) | G35: =G34 | H35: =H34 | I35: =I34 | J35: =IF(J33>J34,J33,J34) | K35: =IF(J33>J34,K33,K34)
A37: Les métaux
A38: métaux | B38: Pièces or | D38: OrPr | E38: =K38-(H38+I38) | G38: =_xlfn.MINIFS(OPdate,OPcompte,B38,OPdevise,D38,OPcatégorie,Solde) | H38: 0 | I38: =SUMIFS(OPequiv_euro,OPcompte,B38,OPdevise,D38,OPcatégorie,"<>"&Spéciale,OPdate,">="&G38) | J38: =SUMIF(AVRintitulé,$B38,AVRdate_solde) | K38: =SUMIF(AVRintitulé,$B38,AVRmontant_solde_euro)
A40: Les cryptos
A41: crypto | B41: BlueWallet BTC | D41: SAT | E41: =K41-(H41+I41) | G41: =_xlfn.MINIFS(OPdate,OPcompte,B41,OPdevise,D41,OPcatégorie,Solde) | H41: 0 | I41: =SUMIFS(OPequiv_euro,OPcompte,B41,OPdevise,D41,OPcatégorie,"<>"&Spéciale,OPdate,">="&G41) | J41: =SUMIF(AVRintitulé,$B41,AVRdate_solde) | K41: =SUMIF(AVRintitulé,$B41,AVRmontant_solde_euro)
A42: crypto | B42: Phoenix Lightning BTC | D42: SAT | E42: =K42-(H42+I42) | G42: =_xlfn.MINIFS(OPdate,OPcompte,B42,OPdevise,D42,OPcatégorie,Solde) | H42: 0 | I42: =SUMIFS(OPequiv_euro,OPcompte,B42,OPdevise,D42,OPcatégorie,"<>"&Spéciale,OPdate,">="&G42) | J42: =SUMIF(AVRintitulé,$B42,AVRdate_solde) | K42: =SUMIF(AVRintitulé,$B42,AVRmontant_solde_euro)
A43: crypto | B43: Compte Kraken BTC | D43: SAT | E43: =K43-(H43+I43) | G43: =_xlfn.MINIFS(OPdate,OPcompte,B43,OPdevise,D43,OPcatégorie,Solde) | H43: 0 | I43: =SUMIFS(OPequiv_euro,OPcompte,B43,OPdevise,D43,OPcatégorie,"<>"&Spéciale,OPdate,">="&G43) | J43: =SUMIF(AVRintitulé,$B43,AVRdate_solde) | K43: =SUMIF(AVRintitulé,$B43,AVRmontant_solde_euro)
A44: crypto | B44: Cake Wallet XMR | D44: XMR | E44: =K44-(H44+I44) | G44: =_xlfn.MINIFS(OPdate,OPcompte,B44,OPdevise,D44,OPcatégorie,Solde) | H44: 0 | I44: =SUMIFS(OPequiv_euro,OPcompte,B44,OPdevise,D44,OPcatégorie,"<>"&Spéciale,OPdate,">="&G44) | J44: =SUMIF(AVRintitulé,$B44,AVRdate_solde) | K44: =SUMIF(AVRintitulé,$B44,AVRmontant_solde_euro)
A46: Les devises
A47: devises | B47: Compte Wise USD | D47: USD | E47: =K47-(H47+I47) | G47: =_xlfn.MINIFS(OPdate,OPcompte,B47,OPdevise,D47,OPcatégorie,Solde) | H47: 0 | I47: =SUMIFS(OPequiv_euro,OPcompte,B47,OPdevise,D47,OPcatégorie,"<>"&Spéciale,OPdate,">="&G47) | J47: =SUMIF(AVRintitulé,$B47,AVRdate_solde) | K47: =SUMIF(AVRintitulé,$B47,AVRmontant_solde_euro)
A48: devises | B48: Compte Wise SGD | D48: SGD | E48: =K48-(H48+I48) | G48: =_xlfn.MINIFS(OPdate,OPcompte,B48,OPdevise,D48,OPcatégorie,Solde) | H48: 0 | I48: =SUMIFS(OPequiv_euro,OPcompte,B48,OPdevise,D48,OPcatégorie,"<>"&Spéciale,OPdate,">="&G48) | J48: =SUMIF(AVRintitulé,$B48,AVRdate_solde) | K48: =SUMIF(AVRintitulé,$B48,AVRmontant_solde_euro)
...

Sheet Opérations
A1: Aujourd‘hui | C1: ="Les données "&année_courante&" et "&année_courante-1&" sont complètes. Les données antérieures sont limitées à certains comptes" | F1: Compteur
A2: =TODAY() | B2: =Contrôles!N$48 | F2: 0 | G2: ="Opérations : "&COUNTIF(OPdate,"<"&DATE(année_courante,12,31))
A3: Date | B3: Libellé | C3: Montant | D3: Devise | E3: Eq. € | F3: Réf. | G3: Catégorie | H3: Compte | I3: Commentaire
A4: 44927 | B4: Relevé compte | C4: 503110 | D4: SAT | G4: #Solde | H4: BlueWallet BTC | I4: SAT = 1 / 100 000 000 Bitcoin
A5: 44927 | B5: Relevé compte | C5: 5000 | D5: EUR | G5: #Solde | H5: Compte chèque commun
A6: 44927 | B6: Relevé compte | C6: 0 | D6: EUR | G6: #Solde | H6: Compte Paypal
A7: 44927 | B7: Relevé compte | C7: 0 | D7: EUR | G7: #Solde | H7: Assurance vie Alice
A8: 44927 | B8: Relevé compte | C8: 0 | D8: EUR | G8: #Solde | H8: Livret A Barnabé
A9: 44927 | B9: Relevé compte | C9: 0 | D9: EUR | G9: #Solde | H9: PEE Alice
A10: 44927 | B10: Relevé compte | C10: 0 | D10: EUR | G10: #Solde | H10: Compte chèque BB
A11: 44927 | B11: Relevé compte | C11: 0 | D11: EUR | G11: #Solde | H11: Portefeuille BB Titres
A12: 44927 | B12: Relevé compte | C12: 0 | D12: EUR | G12: #Solde | H12: Portefeuille DEGIRO Titres
A13: 44927 | B13: Relevé compte | C13: 0 | D13: EUR | G13: #Solde | H13: Portefeuille DEGIRO Réserve
A14: 44927 | B14: Relevé compte | C14: 0 | D14: EUR | G14: #Solde | H14: Compte Wise EUR
A15: 44927 | B15: Relevé compte | C15: 0 | D15: USD | G15: #Solde | H15: Compte Wise USD
A16: 44927 | B16: Relevé compte | C16: 0 | D16: SGD | G16: #Solde | H16: Compte Wise SGD
... A19: 44927 | B19: Relevé compte | C19: 0 | D19: SAT | G19: #Solde | H19: Phoenix Lightning BTC
A20: 44968 | B20: Transfert bitcoin -> lightning | C20: -280000 | D20: SAT | E20: -50 | F20: V1 | G20: Virement | H20: BlueWallet BTC
A21: 44968 | B21: Id | C21: -584 | D21: SAT | G21: Frais bancaires | H21: BlueWallet BTC
A22: 44983 | B22: Id | C22: 280000 | D22: SAT | E22: 50 | F22: V1 | G22: Virement | H22: Phoenix Lightning BTC
A23: 44983 | B23: Id | C23: -1200 | D23: SAT | G23: Frais bancaires | H23: Phoenix Lightning BTC
A24: 44999 | B24: Relevé compte | C24: 0 | D24: EUR | G24: #Solde | H24: Compte Amazon
A25: 45000 | B25: Achat carte cadeau Amazon | C25: -218292 | D25: SAT | E25: -50 | F25: eur2 | G25: Change | H25: BlueWallet BTC
A26: 45000 | B26: Id | C26: -4234 | D26: SAT | G26: Frais bancaires | H26: BlueWallet BTC
A27: 45000 | B27: Id | C27: 50 | D27: EUR | E27: 50 | F27: eur2 | G27: Change | H27: Compte Amazon
A28: 45047 | B28: Relevé compte | C28: 0 | D28: OrPr | G28: #Solde | H28: Pièces or
A29: 45048 | B29: CMA | C29: 14.09344 | D29: OrPr | E29: 990 | F29: OrPr3 | G29: Change | H29: Pièces or
A30: 45048 | B30: Commission CMA | C30: -39.6 | D30: EUR | G30: #Info | H30: Pièces or | I30: Opération non comptabilisée
A31: 45048 | B31: VIR. LOGITEL | C31: -990 | D31: EUR | E31: -990 | F31: OrPr3 | G31: Change | H31: Compte chèque commun
A32: 45292 | B32: Relevé compte | C32: 0 | D32: SAT | G32: #Solde | H32: BlueWallet BTC
A33: 45292 | B33: Relevé compte | C33: 278800 | D33: SAT | G33: #Solde | H33: Phoenix Lightning BTC
A34: 45457 | B34: Relevé compte | C34: 14.09344 | D34: OrPr | G34: #Solde | H34: Pièces or
A35: 45621 | B35: Relevé compte | C35: 2500 | D35: USD | G35: #Solde | H35: Portefeuille eToro USD Réserve
A36: 45621 | B36: Relevé compte | C36: 0 | D36: USD | G36: #Solde | H36: Portefeuille eToro USD Titres
A37: 45622 | B37: Action Air Liquide offert | C37: 10 | D37: USD | E37: 9.6 | G37: Intérêts | H37: Portefeuille eToro USD Titres
A38: 45657 | B38: Relevé compte | C38: 50 | D38: EUR | G38: #Solde | H38: Compte Amazon
A39: 45657 | B39: Relevé compte | C39: 10965 | D39: EUR | G39: #Solde | H39: Créance Francine
A40: 45657 | B40: Relevé compte | C40: 2500 | D40: EUR | G40: #Solde | H40: Espèces
A41: 45661 | B41: Nettoyage | C41: -1000 | D41: EUR | G41: Maison | H41: Espèces
A42: 45663 | B42: VIR. LOGITEL | C42: 500 | D42: EUR | F42: V4 | G42: Virement | H42: Compte chèque commun
...

Sheet Contrôles
A1: =$N$48 | C1: ✓
A2: Compte | B2: Devise | C2: Début | D2: # Déb. | E2: Fin | F2: Fin – début | G2: Montant Déb. | H2: Solde Fin calculé | I2: Solde relevé | J2: Écart | K2: Contrôle écart | L2: Reports # Fin
A4: =Avoirs!A5 | B4: EUR | C4: =_xlfn.MINIFS(OPdate,OPcompte,$A4,OPdevise,$B4,OPcatégorie,Solde) | D4: =COUNTIFS(OPdate,C4,OPcompte,$A4,OPdevise,$B4,OPcatégorie,Solde) | E4: =SUMIF(AVRintitulé,$A4,AVRdate_solde) | F4: =E4-C4 | G4: =SUMIFS(OPmontant,OPdate,$C4,OPcompte,$A4,OPdevise,$B4,OPcatégorie,Solde) | H4: =SUMIFS(OPmontant,OPcompte,$A4,OPdevise,$B4,OPcatégorie,"<>"&Spéciale,OPdate,">"&C4) + $G4 | I4: =SUMIF(AVRintitulé,$A4,AVRmontant_solde) | J4: =ROUND($I4-$H4,2) | K4: Non | L4: =COUNTIFS(OPcompte,$A4,OPdate,$E4,OPdevise,$B4,OPcatégorie,Solde)
A5: =Avoirs!A6 | B5: EUR | C5: =_xlfn.MINIFS(OPdate,OPcompte,$A5,OPdevise,$B5,OPcatégorie,Solde) | D5: =COUNTIFS(OPdate,C5,OPcompte,$A5,OPdevise,$B5,OPcatégorie,Solde) | E5: =SUMIF(AVRintitulé,$A5,AVRdate_solde) | F5: =E5-C5 | G5: =SUMIFS(OPmontant,OPdate,$C5,OPcompte,$A5,OPdevise,$B5,OPcatégorie,Solde) | H5: =SUMIFS(OPmontant,OPcompte,$A5,OPdevise,$B5,OPcatégorie,"<>"&Spéciale,OPdate,">"&C5) + $G5 | I5: =SUMIF(AVRintitulé,$A5,AVRmontant_solde) | J5: =ROUND($I5-$H5,2) | K5: Non | L5: =COUNTIFS(OPcompte,$A5,OPdate,$E5,OPdevise,$B5,OPcatégorie,Solde)
A6: =Avoirs!A7 | B6: EUR | C6: =_xlfn.MINIFS(OPdate,OPcompte,$A6,OPdevise,$B6,OPcatégorie,Solde) | D6: =COUNTIFS(OPdate,C6,OPcompte,$A6,OPdevise,$B6,OPcatégorie,Solde) | E6: =SUMIF(AVRintitulé,$A6,AVRdate_solde) | F6: =E6-C6 | G6: =SUMIFS(OPmontant,OPdate,$C6,OPcompte,$A6,OPdevise,$B6,OPcatégorie,Solde) | H6: =SUMIFS(OPmontant,OPcompte,$A6,OPdevise,$B6,OPcatégorie,"<>"&Spéciale,OPdate,">"&C6) + $G6 | I6: =SUMIF(AVRintitulé,$A6,AVRmontant_solde) | J6: =ROUND($I6-$H6,2) | K6: Non | L6: =COUNTIFS(OPcompte,$A6,OPdate,$E6,OPdevise,$B6,OPcatégorie,Solde)
A7: =Avoirs!A8 | B7: EUR | C7: =_xlfn.MINIFS(OPdate,OPcompte,$A7,OPdevise,$B7,OPcatégorie,Solde) | D7: =COUNTIFS(OPdate,C7,OPcompte,$A7,OPdevise,$B7,OPcatégorie,Solde) | E7: =SUMIF(AVRintitulé,$A7,AVRdate_solde) | F7: =E7-C7 | G7: =SUMIFS(OPmontant,OPdate,$C7,OPcompte,$A7,OPdevise,$B7,OPcatégorie,Solde) | H7: =SUMIFS(OPmontant,OPcompte,$A7,OPdevise,$B7,OPcatégorie,"<>"&Spéciale,OPdate,">"&C7) + $G7 | I7: =SUMIF(AVRintitulé,$A7,AVRmontant_solde) | J7: =ROUND($I7-$H7,2) | K7: Non | L7: =COUNTIFS(OPcompte,$A7,OPdate,$E7,OPdevise,$B7,OPcatégorie,Solde)
A8: =Avoirs!A9 | B8: USD | C8: =_xlfn.MINIFS(OPdate,OPcompte,$A8,OPdevise,$B8,OPcatégorie,Solde) | D8: =COUNTIFS(OPdate,C8,OPcompte,$A8,OPdevise,$B8,OPcatégorie,Solde) | E8: =SUMIF(AVRintitulé,$A8,AVRdate_solde) | F8: =E8-C8 | G8: =SUMIFS(OPmontant,OPdate,$C8,OPcompte,$A8,OPdevise,$B8,OPcatégorie,Solde) | H8: =SUMIFS(OPmontant,OPcompte,$A8,OPdevise,$B8,OPcatégorie,"<>"&Spéciale,OPdate,">"&C8) + $G8 | I8: =SUMIF(AVRintitulé,$A8,AVRmontant_solde) | J8: =ROUND($I8-$H8,2) | K8: Non | L8: =COUNTIFS(OPcompte,$A8,OPdate,$E8,OPdevise,$B8,OPcatégorie,Solde)
A9: =Avoirs!A10 | B9: EUR | C9: =_xlfn.MINIFS(OPdate,OPcompte,$A9,OPdevise,$B9,OPcatégorie,Solde) | D9: =COUNTIFS(OPdate,C9,OPcompte,$A9,OPdevise,$B9,OPcatégorie,Solde) | E9: =SUMIF(AVRintitulé,$A9,AVRdate_solde) | F9: =E9-C9 | G9: =SUMIFS(OPmontant,OPdate,$C9,OPcompte,$A9,OPdevise,$B9,OPcatégorie,Solde) | H9: =SUMIFS(OPmontant,OPcompte,$A9,OPdevise,$B9,OPcatégorie,"<>"&Spéciale,OPdate,">"&C9) + $G9 | I9: =SUMIF(AVRintitulé,$A9,AVRmontant_solde) | J9: =ROUND($I9-$H9,2) | K9: Oui | L9: =COUNTIFS(OPcompte,$A9,OPdate,$E9,OPdevise,$B9,OPcatégorie,Solde)
A10: =Avoirs!A11 | B10: EUR | C10: =_xlfn.MINIFS(OPdate,OPcompte,$A10,OPdevise,$B10,OPcatégorie,Solde) | D10: =COUNTIFS(OPdate,C10,OPcompte,$A10,OPdevise,$B10,OPcatégorie,Solde) | E10: =SUMIF(AVRintitulé,$A10,AVRdate_solde) | F10: =E10-C10 | G10: =SUMIFS(OPmontant,OPdate,$C10,OPcompte,$A10,OPdevise,$B10,OPcatégorie,Solde) | H10: =SUMIFS(OPmontant,OPcompte,$A10,OPdevise,$B10,OPcatégorie,"<>"&Spéciale,OPdate,">"&C10) + $G10 | I10: =SUMIF(AVRintitulé,$A10,AVRmontant_solde) | J10: =ROUND($I10-$H10,2) | K10: Oui | L10: =COUNTIFS(OPcompte,$A10,OPdate,$E10,OPdevise,$B10,OPcatégorie,Solde)
A11: =Avoirs!A12 | B11: EUR | C11: =_xlfn.MINIFS(OPdate,OPcompte,$A11,OPdevise,$B11,OPcatégorie,Solde) | D11: =COUNTIFS(OPdate,C11,OPcompte,$A11,OPdevise,$B11,OPcatégorie,Solde) | E11: =SUMIF(AVRintitulé,$A11,AVRdate_solde) | F11: =E11-C11 | G11: =SUMIFS(OPmontant,OPdate,$C11,OPcompte,$A11,OPdevise,$B11,OPcatégorie,Solde) | H11: =SUMIFS(OPmontant,OPcompte,$A11,OPdevise,$B11,OPcatégorie,"<>"&Spéciale,OPdate,">"&C11) + $G11 | I11: =SUMIF(AVRintitulé,$A11,AVRmontant_solde) | J11: =ROUND($I11-$H11,2) | K11: Oui | L11: =COUNTIFS(OPcompte,$A11,OPdate,$E11,OPdevise,$B11,OPcatégorie,Solde)
A12: =Avoirs!A13 | B12: EUR | C12: =_xlfn.MINIFS(OPdate,OPcompte,$A12,OPdevise,$B12,OPcatégorie,Solde) | D12: =COUNTIFS(OPdate,C12,OPcompte,$A12,OPdevise,$B12,OPcatégorie,Solde) | E12: =SUMIF(AVRintitulé,$A12,AVRdate_solde) | F12: =E12-C12 | G12: =SUMIFS(OPmontant,OPdate,$C12,OPcompte,$A12,OPdevise,$B12,OPcatégorie,Solde) | H12: =SUMIFS(OPmontant,OPcompte,$A12,OPdevise,$B12,OPcatégorie,"<>"&Spéciale,OPdate,">"&C12) + $G12 | I12: =SUMIF(AVRintitulé,$A12,AVRmontant_solde) | J12: =ROUND($I12-$H12,2) | K12: Oui | L12: =COUNTIFS(OPcompte,$A12,OPdate,$E12,OPdevise,$B12,OPcatégorie,Solde)
A13: =Avoirs!A14 | B13: EUR | C13: =_xlfn.MINIFS(OPdate,OPcompte,$A13,OPdevise,$B13,OPcatégorie,Solde) | D13: =COUNTIFS(OPdate,C13,OPcompte,$A13,OPdevise,$B13,OPcatégorie,Solde) | E13: =SUMIF(AVRintitulé,$A13,AVRdate_solde) | F13: =E13-C13 | G13: =SUMIFS(OPmontant,OPdate,$C13,OPcompte,$A13,OPdevise,$B13,OPcatégorie,Solde) | H13: =SUMIFS(OPmontant,OPcompte,$A13,OPdevise,$B13,OPcatégorie,"<>"&Spéciale,OPdate,">"&C13) + $G13 | I13: =SUMIF(AVRintitulé,$A13,AVRmontant_solde) | J13: =ROUND($I13-$H13,2) | K13: Oui | L13: =COUNTIFS(OPcompte,$A13,OPdate,$E13,OPdevise,$B13,OPcatégorie,Solde)
A14: =Avoirs!A15 | B14: EUR | C14: =_xlfn.MINIFS(OPdate,OPcompte,$A14,OPdevise,$B14,OPcatégorie,Solde) | D14: =COUNTIFS(OPdate,C14,OPcompte,$A14,OPdevise,$B14,OPcatégorie,Solde) | E14: =SUMIF(AVRintitulé,$A14,AVRdate_solde) | F14: =E14-C14 | G14: =SUMIFS(OPmontant,OPdate,$C14,OPcompte,$A14,OPdevise,$B14,OPcatégorie,Solde) | H14: =SUMIFS(OPmontant,OPcompte,$A14,OPdevise,$B14,OPcatégorie,"<>"&Spéciale,OPdate,">"&C14) + $G14 | I14: =SUMIF(AVRintitulé,$A14,AVRmontant_solde) | J14: =ROUND($I14-$H14,2) | K14: Oui | L14: =COUNTIFS(OPcompte,$A14,OPdate,$E14,OPdevise,$B14,OPcatégorie,Solde)
A15: =Avoirs!A16 | B15: EUR | C15: =_xlfn.MINIFS(OPdate,OPcompte,$A15,OPdevise,$B15,OPcatégorie,Solde) | D15: =COUNTIFS(OPdate,C15,OPcompte,$A15,OPdevise,$B15,OPcatégorie,Solde) | E15: =SUMIF(AVRintitulé,$A15,AVRdate_solde) | F15: =E15-C15 | G15: =SUMIFS(OPmontant,OPdate,$C15,OPcompte,$A15,OPdevise,$B15,OPcatégorie,Solde) | H15: =SUMIFS(OPmontant,OPcompte,$A15,OPdevise,$B15,OPcatégorie,"<>"&Spéciale,OPdate,">"&C15) + $G15 | I15: =SUMIF(AVRintitulé,$A15,AVRmontant_solde) | J15: =ROUND($I15-$H15,2) | K15: Oui | L15: =COUNTIFS(OPcompte,$A15,OPdate,$E15,OPdevise,$B15,OPcatégorie,Solde)
... A26: =Avoirs!A27 | B26: OrPr | C26: =_xlfn.MINIFS(OPdate,OPcompte,$A26,OPdevise,$B26,OPcatégorie,Solde) | D26: =COUNTIFS(OPdate,C26,OPcompte,$A26,OPdevise,$B26,OPcatégorie,Solde) | E26: =SUMIF(AVRintitulé,$A26,AVRdate_solde) | F26: =E26-C26 | G26: =SUMIFS(OPmontant,OPdate,$C26,OPcompte,$A26,OPdevise,$B26,OPcatégorie,Solde) | H26: =SUMIFS(OPmontant,OPcompte,$A26,OPdevise,$B26,OPcatégorie,"<>"&Spéciale,OPdate,">"&C26) + $G26 | I26: =SUMIF(AVRintitulé,$A26,AVRmontant_solde) | J26: =ROUND($I26-$H26,2) | K26: Oui | L26: =COUNTIFS(OPcompte,$A26,OPdate,$E26,OPdevise,$B26,OPcatégorie,Solde)
A27: =Avoirs!A28 | C27: =_xlfn.MINIFS(OPdate,OPcompte,$A27,OPdevise,$B27,OPcatégorie,Solde) | D27: =COUNTIFS(OPdate,C27,OPcompte,$A27,OPdevise,$B27,OPcatégorie,Solde) | E27: =SUMIF(AVRintitulé,$A27,AVRdate_solde) | F27: =E27-C27 | G27: =SUMIFS(OPmontant,OPdate,$C27,OPcompte,$A27,OPdevise,$B27,OPcatégorie,Solde) | H27: =SUMIFS(OPmontant,OPcompte,$A27,OPdevise,$B27,OPcatégorie,"<>"&Spéciale,OPdate,">"&C27) + $G27 | I27: =SUMIF(AVRintitulé,$A27,AVRmontant_solde) | J27: =ROUND($I27-$H27,2) | K27: Non | L27: =COUNTIFS(OPcompte,$A27,OPdate,$E27,OPdevise,$B27,OPcatégorie,Solde)
A28: =Avoirs!A29 | C28: =_xlfn.MINIFS(OPdate,OPcompte,$A28,OPdevise,$B28,OPcatégorie,Solde) | D28: =COUNTIFS(OPdate,C28,OPcompte,$A28,OPdevise,$B28,OPcatégorie,Solde) | E28: =SUMIF(AVRintitulé,$A28,AVRdate_solde) | F28: =E28-C28 | G28: =SUMIFS(OPmontant,OPdate,$C28,OPcompte,$A28,OPdevise,$B28,OPcatégorie,Solde) | H28: =SUMIFS(OPmontant,OPcompte,$A28,OPdevise,$B28,OPcatégorie,"<>"&Spéciale,OPdate,">"&C28) + $G28 | I28: =SUMIF(AVRintitulé,$A28,AVRmontant_solde) | J28: =ROUND($I28-$H28,2) | K28: Non | L28: =COUNTIFS(OPcompte,$A28,OPdate,$E28,OPdevise,$B28,OPcatégorie,Solde)
A29: =Avoirs!A30 | C29: =_xlfn.MINIFS(OPdate,OPcompte,$A29,OPdevise,$B29,OPcatégorie,Solde) | D29: =COUNTIFS(OPdate,C29,OPcompte,$A29,OPdevise,$B29,OPcatégorie,Solde) | E29: =SUMIF(AVRintitulé,$A29,AVRdate_solde) | F29: =E29-C29 | G29: =SUMIFS(OPmontant,OPdate,$C29,OPcompte,$A29,OPdevise,$B29,OPcatégorie,Solde) | H29: =SUMIFS(OPmontant,OPcompte,$A29,OPdevise,$B29,OPcatégorie,"<>"&Spéciale,OPdate,">"&C29) + $G29 | I29: =SUMIF(AVRintitulé,$A29,AVRmontant_solde) | J29: =ROUND($I29-$H29,2) | K29: Non | L29: =COUNTIFS(OPcompte,$A29,OPdate,$E29,OPdevise,$B29,OPcatégorie,Solde)
D31: =SUMPRODUCT(($K4:$K29="Oui")*(D4:D29<>1)*(D4:D29<>"")) | F31: =SUMPRODUCT(($K4:$K29="Oui")*($F4:$F29=0)) | L31: =SUMPRODUCT(($K4:$K29="Oui")*(L4:L29<>1)*(L4:L29<>""))
M33: CONTRÔLES
M34: Type de contrôle | N34: Affichage | O34: Général | P34: EUR | Q34: XAU | R34: BTC | S34: USD | T34: SGD | U34: OrPr | V34: SAT | W34: XMR
Q35: =Cotations!$D$4 | R35: =Cotations!$D$10 | S35: =Cotations!$D$9 | T35: =Cotations!$D$8 | U35: =Cotations!$D$7 | V35: =Cotations!$D$6 | W35: =Cotations!$D$5
M36: COMPTES (de début #Solde à fin #Solde) | N36: =IF(SUM($O36:$P36)=0,"✓","✗") | O36: =$D$31+$L$31+$F$31 | P36: =COUNTIFS($B4:$B29,P$34,$K4:$K29,"Oui")-COUNTIFS($B4:$B29,P$34,$K4:$K29,"Oui",$J4:$J29,0) | Q36: =COUNTIFS($B4:$B29,Q$34,$K4:$K29,"Oui")-COUNTIFS($B4:$B29,Q$34,$K4:$K29,"Oui",$J4:$J29,0) | R36: =COUNTIFS($B4:$B29,R$34,$K4:$K29,"Oui")-COUNTIFS($B4:$B29,R$34,$K4:$K29,"Oui",$J4:$J29,0) | S36: =COUNTIFS($B4:$B29,S$34,$K4:$K29,"Oui")-COUNTIFS($B4:$B29,S$34,$K4:$K29,"Oui",$J4:$J29,0) | T36: =COUNTIFS($B4:$B29,T$34,$K4:$K29,"Oui")-COUNTIFS($B4:$B29,T$34,$K4:$K29,"Oui",$J4:$J29,0) | U36: =COUNTIFS($B4:$B29,U$34,$K4:$K29,"Oui")-COUNTIFS($B4:$B29,U$34,$K4:$K29,"Oui",$J4:$J29,0) | V36: =COUNTIFS($B4:$B29,V$34,$K4:$K29,"Oui")-COUNTIFS($B4:$B29,V$34,$K4:$K29,"Oui",$J4:$J29,0) | W36: =COUNTIFS($B4:$B29,W$34,$K4:$K29,"Oui")-COUNTIFS($B4:$B29,W$34,$K4:$K29,"Oui",$J4:$J29,0)
M37: CATÉGORIES (année glissante) | N37: =IF(SUM($O37:$P37)=0,"✓","✗") | P37: =Budget!F$38 | Q37: =Budget!G$38 | R37: =Budget!H$38 | S37: =Budget!I$38 | T37: =Budget!J$38 | U37: =Budget!K$38 | V37: =Budget!L$38 | W37: =Budget!M$38
M38: Date | N38: =IF(O38=0,"✓","⚠") | O38: =COUNTIF(OPdate,"<"&DATE(2020,1,1))+COUNTIF(OPdate,">"&DATE(année_courante,12,31))
M39: Appariements | N39: =IF(O39=0,"✓","⚠") | O39: =COUNTIFS(OPréf,"-") | P39: =COUNTIFS(OPréf,"-",OPdevise,P$34) | Q39: =COUNTIFS(OPréf,"-",OPdevise,Q$34) | R39: =COUNTIFS(OPréf,"-",OPdevise,R$34) | S39: =COUNTIFS(OPréf,"-",OPdevise,S$34) | T39: =COUNTIFS(OPréf,"-",OPdevise,T$34) | U39: =COUNTIFS(OPréf,"-",OPdevise,U$34) | V39: =COUNTIFS(OPréf,"-",OPdevise,V$34) | W39: =COUNTIFS(OPréf,"-",OPdevise,W$34)
M40: Balances | N40: =IF(O40=0,"✓","⚠") | O40: =3-COUNTIFS(O41:O45,0) | P40: =COUNTA($M41:$M43)-COUNTIFS(P41:P43,0) | Q40: =COUNTA($M41:$M43)-COUNTIFS(Q41:Q43,0) | R40: =COUNTA($M41:$M43)-COUNTIFS(R41:R43,0) | S40: =COUNTA($M41:$M43)-COUNTIFS(S41:S43,0) | T40: =COUNTA($M41:$M43)-COUNTIFS(T41:T43,0) | U40: =COUNTA($M41:$M43)-COUNTIFS(U41:U43,0) | V40: =COUNTA($M41:$M43)-COUNTIFS(V41:V43,0) | W40: =COUNTA($M41:$M43)-COUNTIFS(W41:W43,0)
M41: Virements | P41: =ROUND(SUMIFS(OPmontant,OPdevise,P$34,OPcatégorie,"Virement*"),0) | Q41: =ROUND(SUMIFS(OPmontant,OPdevise,Q$34,OPcatégorie,"Virement*"),0) | R41: =ROUND(SUMIFS(OPmontant,OPdevise,R$34,OPcatégorie,"Virement*"),0) | S41: =ROUND(SUMIFS(OPmontant,OPdevise,S$34,OPcatégorie,"Virement*"),0) | T41: =ROUND(SUMIFS(OPmontant,OPdevise,T$34,OPcatégorie,"Virement*"),0) | U41: =ROUND(SUMIFS(OPmontant,OPdevise,U$34,OPcatégorie,"Virement*"),0) | V41: =ROUND(SUMIFS(OPmontant,OPdevise,V$34,OPcatégorie,"Virement*"),0) | W41: =ROUND(SUMIFS(OPmontant,OPdevise,W$34,OPcatégorie,"Virement*"),0)
M42: € | O42: =SUM(P42) | P42: =ROUND(SUMIFS(OPmontant,OPdevise,P$34,OPcatégorie,"Virement*"),0) | Q42: =ROUND(SUMIFS(OPmontant,OPdevise,Q$34,OPcatégorie,"Virement*"),0)*Q$35 | R42: =ROUND(SUMIFS(OPmontant,OPdevise,R$34,OPcatégorie,"Virement*"),0)*R$35 | S42: =ROUND(SUMIFS(OPmontant,OPdevise,S$34,OPcatégorie,"Virement*"),0)*S$35 | T42: =ROUND(SUMIFS(OPmontant,OPdevise,T$34,OPcatégorie,"Virement*"),0)*T$35 | U42: =ROUND(SUMIFS(OPmontant,OPdevise,U$34,OPcatégorie,"Virement*"),0)*U$35 | V42: =ROUND(SUMIFS(OPmontant,OPdevise,V$34,OPcatégorie,"Virement*"),0)*V$35 | W42: =ROUND(SUMIFS(OPmontant,OPdevise,W$34,OPcatégorie,"Virement*"),0)*W$35
M43: Titres | P43: =ROUND(SUMIFS(OPmontant,OPdevise,P$34,OPcatégorie,"*titres"),0) | Q43: =ROUND(SUMIFS(OPmontant,OPdevise,Q$34,OPcatégorie,"*titres"),0) | R43: =ROUND(SUMIFS(OPmontant,OPdevise,R$34,OPcatégorie,"*titres"),0) | S43: =ROUND(SUMIFS(OPmontant,OPdevise,S$34,OPcatégorie,"*titres"),0) | T43: =ROUND(SUMIFS(OPmontant,OPdevise,T$34,OPcatégorie,"*titres"),0) | U43: =ROUND(SUMIFS(OPmontant,OPdevise,U$34,OPcatégorie,"*titres"),0) | V43: =ROUND(SUMIFS(OPmontant,OPdevise,V$34,OPcatégorie,"*titres"),0) | W43: =ROUND(SUMIFS(OPmontant,OPdevise,W$34,OPcatégorie,"*titres"),0)
M44: € | O44: =SUM(P44) | P44: =ROUND(SUMIFS(OPmontant,OPdevise,P$34,OPcatégorie,"*titres"),0) | Q44: =ROUND(SUMIFS(OPmontant,OPdevise,Q$34,OPcatégorie,"*titres"),0)*Q$35 | R44: =ROUND(SUMIFS(OPmontant,OPdevise,R$34,OPcatégorie,"*titres"),0)*R$35 | S44: =ROUND(SUMIFS(OPmontant,OPdevise,S$34,OPcatégorie,"*titres"),0)*S$35 | T44: =ROUND(SUMIFS(OPmontant,OPdevise,T$34,OPcatégorie,"*titres"),0)*T$35 | U44: =ROUND(SUMIFS(OPmontant,OPdevise,U$34,OPcatégorie,"*titres"),0)*U$35 | V44: =ROUND(SUMIFS(OPmontant,OPdevise,V$34,OPcatégorie,"*titres"),0)*V$35 | W44: =ROUND(SUMIFS(OPmontant,OPdevise,W$34,OPcatégorie,"*titres"),0)*W$35
M45: Changes Eq € | O45: =SUMIFS(OPequiv_euro,OPcatégorie,"Change") + SUMIFS(OPequiv_euro,OPcatégorie,"Achat métaux") | P45: =SUMIFS(OPequiv_euro,OPdevise,P$34,OPcatégorie,"Change")+SUMIFS(OPequiv_euro,OPdevise,P$34,OPcatégorie,"Achat métaux") | Q45: =SUMIFS(OPequiv_euro,OPdevise,Q$34,OPcatégorie,"Change")+SUMIFS(OPequiv_euro,OPdevise,Q$34,OPcatégorie,"Achat métaux") | R45: =SUMIFS(OPequiv_euro,OPdevise,R$34,OPcatégorie,"Change")+SUMIFS(OPequiv_euro,OPdevise,R$34,OPcatégorie,"Achat métaux") | S45: =SUMIFS(OPequiv_euro,OPdevise,S$34,OPcatégorie,"Change")+SUMIFS(OPequiv_euro,OPdevise,S$34,OPcatégorie,"Achat métaux") | T45: =SUMIFS(OPequiv_euro,OPdevise,T$34,OPcatégorie,"Change")+SUMIFS(OPequiv_euro,OPdevise,T$34,OPcatégorie,"Achat métaux") | U45: =SUMIFS(OPequiv_euro,OPdevise,U$34,OPcatégorie,"Change")+SUMIFS(OPequiv_euro,OPdevise,U$34,OPcatégorie,"Achat métaux") | V45: =SUMIFS(OPequiv_euro,OPdevise,V$34,OPcatégorie,"Change")+SUMIFS(OPequiv_euro,OPdevise,V$34,OPcatégorie,"Achat métaux") | W45: =SUMIFS(OPequiv_euro,OPdevise,W$34,OPcatégorie,"Change")+SUMIFS(OPequiv_euro,OPdevise,W$34,OPcatégorie,"Achat métaux")
M46: Total € | O46: =O42+O44+O45 | P46: =P42+P44+P45 | Q46: =Q42+Q44+Q45 | R46: =R42+R44+R45 | S46: =S42+S44+S45 | T46: =T42+T44+T45 | U46: =U42+U44+U45 | V46: =V42+V44+V45 | W46: =W42+W44+W45
M47: INCONNUS (Comptes) | N47: =IF(O47=0,"✓","✗") | O47: =SUMPRODUCT((COUNTIF(AVRintitulé,OPcompte)=0)*(OPcompte<>""))
M48: Synthèse des contrôles | N48: =IF(N36&N37&N38&$N39&$N40&$N47="✓✓✓✓✓✓","✓",$N36&$N37&N38&$N39&$N40&$N47) | O48: =O44+O46+O47

Sheet Cotations
A1: =Contrôles!$N$48 | D1: =année_courante
A2: Devise / unité | B2: Nature | C2: Code | D2: Cours en Euro | E2: Date | F2: Cours de l’Euro
A3: Euro | B3: primaire | C3: EUR | D3: 1
A4: Gramme d'or Spot | B4: primaire | C4: XAU | D4: 144.12 | E4: 28/03/2026
A5: Monero | B5: primaire | C5: XMR | D5: 305.02 | E5: 28/03/2026
A6: Satoshi (1 / 100 000 000 Bitcoin) | B6: dérivée | C6: SAT | D6: 0.00061009
A7: Gramme d'or Premium (pièces) | B7: dérivée | C7: OrPr | D7: 150.31716
A8: Dollar Singapour | B8: primaire | C8: SGD | D8: 0.6776 | E8: 28/03/2026
A9: Dollar US | B9: primaire | C9: USD | D9: 0.8635 | E9: 28/03/2026
A10: Bitcoin | B10: primaire | C10: BTC | D10: 61009 | E10: 28/03/2026
